Workbook

Sheet POST IPO 보고서
B2: POST IPO 모니터링 보고서
B3: 기준일: 2026-06-04 | 분석 대상: 138개 종목 | 2년 이내 신규 상장주
B6: 전체 종목 | D6: A등급 | F6: B등급 | H6: 50점 이상 종목수 | J6: RSI>65
B7: 138 | D7: 0 | F7: 7 | H7: 49 | J7: =COUNTIF(전체!Q2:Q10000,">65")
B10: [Top] 추천종목 (종합스코어 50점 이상) | Q10: 구분 | R10: 종목수
B11: 순위 | C11: 종목명 | D11: 종합점수 | E11: 모멘텀 | F11: 수급 | G11: 거래량 | H11: RSI | I11: 등급 | J11: RSI신호 | K11: 등급변화 | L11: 점수변화량 | M11: 모멘텀Δ | N11: 수급Δ | O11: 거래량Δ | Q11: 강세 (A+B등급) | R11: 7
B12: 1 | C12: M83 | D12: 74.3 | E12: 98.1 | F12: 49.8 | G12: 100 | H12: 65.950345 | I12: B | J12: ★ | K12: =IFERROR(IF(I12=INDEX(전체_전일자!1:1048576,MATCH(C12,전체_전일자!B:B,0),MATCH("등급",전체_전일자!1:1,0)),"유지",INDEX(전체_전일자!1:1048576,MATCH(C12,전체_전일자!B:B,0),MATCH("등급",전체_전일자!1:1,0))&" → "&I12),"") | L12: =IFERROR(D12-INDEX(전체_전일자!1:1048576,MATCH(C12,전체_전일자!B:B,0),MATCH("종합스코어",전체_전일자!1:1,0)),"") | M12: =IFERROR(E12-INDEX(전체_전일자!1:1048576,MATCH(C12,전체_전일자!B:B,0),MATCH("모멘텀스코어",전체_전일자!1:1,0)),"") | N12: =IFERROR(F12-INDEX(전체_전일자!1:1048576,MATCH(C12,전체_전일자!B:B,0),MATCH("수급스코어",전체_전일자!1:1,0)),"") | O12: =IFERROR(G12-INDEX(전체_전일자!1:1048576,MATCH(C12,전체_전일자!B:B,0),MATCH("거래량스코어",전체_전일자!1:1,0)),"") | Q12: 중립 (C등급) | R12: 42
B13: 2 | C13: 디앤디파마텍 | D13: 73.6 | E13: 98.8 | F13: 50 | G13: 94.8 | H13: 59.719538 | I13: B | K13: =IFERROR(IF(I13=INDEX(전체_전일자!1:1048576,MATCH(C13,전체_전일자!B:B,0),MATCH("등급",전체_전일자!1:1,0)),"유지",INDEX(전체_전일자!1:1048576,MATCH(C13,전체_전일자!B:B,0),MATCH("등급",전체_전일자!1:1,0))&" → "&I13),"") | L13: =IFERROR(D13-INDEX(전체_전일자!1:1048576,MATCH(C13,전체_전일자!B:B,0),MATCH("종합스코어",전체_전일자!1:1,0)),"") | M13: =IFERROR(E13-INDEX(전체_전일자!1:1048576,MATCH(C13,전체_전일자!B:B,0),MATCH("모멘텀스코어",전체_전일자!1:1,0)),"") | N13: =IFERROR(F13-INDEX(전체_전일자!1:1048576,MATCH(C13,전체_전일자!B:B,0),MATCH("수급스코어",전체_전일자!1:1,0)),"") | O13: =IFERROR(G13-INDEX(전체_전일자!1:1048576,MATCH(C13,전체_전일자!B:B,0),MATCH("거래량스코어",전체_전일자!1:1,0)),"") | Q13: 약세 (D+F등급) | R13: 89
B14: 3 | C14: 에스켐 | D14: 72 | E14: 90.3 | F14: 54.2 | G14: 88.9 | H14: 44.206431 | I14: B | K14: =IFERROR(IF(I14=INDEX(전체_전일자!1:1048576,MATCH(C14,전체_전일자!B:B,0),MATCH("등급",전체_전일자!1:1,0)),"유지",INDEX(전체_전일자!1:1048576,MATCH(C14,전체_전일자!B:B,0),MATCH("등급",전체_전일자!1:1,0))&" → "&I14),"") | L14: =IFERROR(D14-INDEX(전체_전일자!1:1048576,MATCH(C14,전체_전일자!B:B,0),MATCH("종합스코어",전체_전일자!1:1,0)),"") | M14: =IFERROR(E14-INDEX(전체_전일자!1:1048576,MATCH(C14,전체_전일자!B:B,0),MATCH("모멘텀스코어",전체_전일자!1:1,0)),"") | N14: =IFERROR(F14-INDEX(전체_전일자!1:1048576,MATCH(C14,전체_전일자!B:B,0),MATCH("수급스코어",전체_전일자!1:1,0)),"") | O14: =IFERROR(G14-INDEX(전체_전일자!1:1048576,MATCH(C14,전체_전일자!B:B,0),MATCH("거래량스코어",전체_전일자!1:1,0)),"")
B15: 4 | C15: 노머스 | D15: 68.3 | E15: 46.6 | F15: 79.9 | G15: 71.9 | H15: 35.38595 | I15: B | K15: =IFERROR(IF(I15=INDEX(전체_전일자!1:1048576,MATCH(C15,전체_전일자!B:B,0),MATCH("등급",전체_전일자!1:1,0)),"유지",INDEX(전체_전일자!1:1048576,MATCH(C15,전체_전일자!B:B,0),MATCH("등급",전체_전일자!1:1,0))&" → "&I15),"") | L15: =IFERROR(D15-INDEX(전체_전일자!1:1048576,MATCH(C15,전체_전일자!B:B,0),MATCH("종합스코어",전체_전일자!1:1,0)),"") | M15: =IFERROR(E15-INDEX(전체_전일자!1:1048576,MATCH(C15,전체_전일자!B:B,0),MATCH("모멘텀스코어",전체_전일자!1:1,0)),"") | N15: =IFERROR(F15-INDEX(전체_전일자!1:1048576,MATCH(C15,전체_전일자!B:B,0),MATCH("수급스코어",전체_전일자!1:1,0)),"") | O15: =IFERROR(G15-INDEX(전체_전일자!1:1048576,MATCH(C15,전체_전일자!B:B,0),MATCH("거래량스코어",전체_전일자!1:1,0)),"")
B16: 5 | C16: 에이치브이엠 | D16: 68.3 | E16: 70.5 | F16: 67 | G16: 68.1 | H16: 50.032472 | I16: B | K16: =IFERROR(IF(I16=INDEX(전체_전일자!1:1048576,MATCH(C16,전체_전일자!B:B,0),MATCH("등급",전체_전일자!1:1,0)),"유지",INDEX(전체_전일자!1:1048576,MATCH(C16,전체_전일자!B:B,0),MATCH("등급",전체_전일자!1:1,0))&" → "&I16),"") | L16: =IFERROR(D16-INDEX(전체_전일자!1:1048576,MATCH(C16,전체_전일자!B:B,0),MATCH("종합스코어",전체_전일자!1:1,0)),"") | M16: =IFERROR(E16-INDEX(전체_전일자!1:1048576,MATCH(C16,전체_전일자!B:B,0),MATCH("모멘텀스코어",전체_전일자!1:1,0)),"") | N16: =IFERROR(F16-INDEX(전체_전일자!1:1048576,MATCH(C16,전체_전일자!B:B,0),MATCH("수급스코어",전체_전일자!1:1,0)),"") | O16: =IFERROR(G16-INDEX(전체_전일자!1:1048576,MATCH(C16,전체_전일자!B:B,0),MATCH("거래량스코어",전체_전일자!1:1,0)),"")
B17: 6 | C17: 케이뱅크 | D17: 67.6 | E17: 75.6 | F17: 67.9 | G17: 54.8 | H17: 39.379227 | I17: B | K17: =IFERROR(IF(I17=INDEX(전체_전일자!1:1048576,MATCH(C17,전체_전일자!B:B,0),MATCH("등급",전체_전일자!1:1,0)),"유지",INDEX(전체_전일자!1:1048576,MATCH(C17,전체_전일자!B:B,0),MATCH("등급",전체_전일자!1:1,0))&" → "&I17),"") | L17: =IFERROR(D17-INDEX(전체_전일자!1:1048576,MATCH(C17,전체_전일자!B:B,0),MATCH("종합스코어",전체_전일자!1:1,0)),"") | M17: =IFERROR(E17-INDEX(전체_전일자!1:1048576,MATCH(C17,전체_전일자!B:B,0),MATCH("모멘텀스코어",전체_전일자!1:1,0)),"") | N17: =IFERROR(F17-INDEX(전체_전일자!1:1048576,MATCH(C17,전체_전일자!B:B,0),MATCH("수급스코어",전체_전일자!1:1,0)),"") | O17: =IFERROR(G17-INDEX(전체_전일자!1:1048576,MATCH(C17,전체_전일자!B:B,0),MATCH("거래량스코어",전체_전일자!1:1,0)),"")
B18: 7 | C18: 벡트 | D18: 65.2 | E18: 52.4 | F18: 60.2 | G18: 97 | H18: 34.928758 | I18: B | K18: =IFERROR(IF(I18=INDEX(전체_전일자!1:1048576,MATCH(C18,전체_전일자!B:B,0),MATCH("등급",전체_전일자!1:1,0)),"유지",INDEX(전체_전일자!1:1048576,MATCH(C18,전체_전일자!B:B,0),MATCH("등급",전체_전일자!1:1,0))&" → "&I18),"") | L18: =IFERROR(D18-INDEX(전체_전일자!1:1048576,MATCH(C18,전체_전일자!B:B,0),MATCH("종합스코어",전체_전일자!1:1,0)),"") | M18: =IFERROR(E18-INDEX(전체_전일자!1:1048576,MATCH(C18,전체_전일자!B:B,0),MATCH("모멘텀스코어",전체_전일자!1:1,0)),"") | N18: =IFERROR(F18-INDEX(전체_전일자!1:1048576,MATCH(C18,전체_전일자!B:B,0),MATCH("수급스코어",전체_전일자!1:1,0)),"") | O18: =IFERROR(G18-INDEX(전체_전일자!1:1048576,MATCH(C18,전체_전일자!B:B,0),MATCH("거래량스코어",전체_전일자!1:1,0)),"")
B19: 8 | C19: 한텍 | D19: 64.5 | E19: 87.6 | F19: 39.7 | G19: 91.9 | H19: 45.700896 | I19: C | K19: =IFERROR(IF(I19=INDEX(전체_전일자!1:1048576,MATCH(C19,전체_전일자!B:B,0),MATCH("등급",전체_전일자!1:1,0)),"유지",INDEX(전체_전일자!1:1048576,MATCH(C19,전체_전일자!B:B,0),MATCH("등급",전체_전일자!1:1,0))&" → "&I19),"") | L19: =IFERROR(D19-INDEX(전체_전일자!1:1048576,MATCH(C19,전체_전일자!B:B,0),MATCH("종합스코어",전체_전일자!1:1,0)),"") | M19: =IFERROR(E19-INDEX(전체_전일자!1:1048576,MATCH(C19,전체_전일자!B:B,0),MATCH("모멘텀스코어",전체_전일자!1:1,0)),"") | N19: =IFERROR(F19-INDEX(전체_전일자!1:1048576,MATCH(C19,전체_전일자!B:B,0),MATCH("수급스코어",전체_전일자!1:1,0)),"") | O19: =IFERROR(G19-INDEX(전체_전일자!1:1048576,MATCH(C19,전체_전일자!B:B,0),MATCH("거래량스코어",전체_전일자!1:1,0)),"")
B20: 9 | C20: 한켐 | D20: 64.3 | E20: 71.5 | F20: 67 | G20: 46.7 | H20: 60.112585 | I20: C | K20: =IFERROR(IF(I20=INDEX(전체_전일자!1:1048576,MATCH(C20,전체_전일자!B:B,0),MATCH("등급",전체_전일자!1:1,0)),"유지",INDEX(전체_전일자!1:1048576,MATCH(C20,전체_전일자!B:B,0),MATCH("등급",전체_전일자!1:1,0))&" → "&I20),"") | L20: =IFERROR(D20-INDEX(전체_전일자!1:1048576,MATCH(C20,전체_전일자!B:B,0),MATCH("종합스코어",전체_전일자!1:1,0)),"") | M20: =IFERROR(E20-INDEX(전체_전일자!1:1048576,MATCH(C20,전체_전일자!B:B,0),MATCH("모멘텀스코어",전체_전일자!1:1,0)),"") | N20: =IFERROR(F20-INDEX(전체_전일자!1:1048576,MATCH(C20,전체_전일자!B:B,0),MATCH("수급스코어",전체_전일자!1:1,0)),"") | O20: =IFERROR(G20-INDEX(전체_전일자!1:1048576,MATCH(C20,전체_전일자!B:B,0),MATCH("거래량스코어",전체_전일자!1:1,0)),"")
B21: 10 | C21: 클로봇 | D21: 64.2 | E21: 71.5 | F21: 50.2 | G21: 88.1 | H21: 50.165413 | I21: C | K21: =IFERROR(IF(I21=INDEX(전체_전일자!1:1048576,MATCH(C21,전체_전일자!B:B,0),MATCH("등급",전체_전일자!1:1,0)),"유지",INDEX(전체_전일자!1:1048576,MATCH(C21,전체_전일자!B:B,0),MATCH("등급",전체_전일자!1:1,0))&" → "&I21),"") | L21: =IFERROR(D21-INDEX(전체_전일자!1:1048576,MATCH(C21,전체_전일자!B:B,0),MATCH("종합스코어",전체_전일자!1:1,0)),"") | M21: =IFERROR(E21-INDEX(전체_전일자!1:1048576,MATCH(C21,전체_전일자!B:B,0),MATCH("모멘텀스코어",전체_전일자!1:1,0)),"") | N21: =IFERROR(F21-INDEX(전체_전일자!1:1048576,MATCH(C21,전체_전일자!B:B,0),MATCH("수급스코어",전체_전일자!1:1,0)),"") | O21: =IFERROR(G21-INDEX(전체_전일자!1:1048576,MATCH(C21,전체_전일자!B:B,0),MATCH("거래량스코어",전체_전일자!1:1,0)),"")
B22: 11 | C22: 달바글로벌 | D22: 64.1 | E22: 69.5 | F22: 50.7 | G22: 89.6 | H22: 43.867101 | I22: C | K22: =IFERROR(IF(I22=INDEX(전체_전일자!1:1048576,MATCH(C22,전체_전일자!B:B,0),MATCH("등급",전체_전일자!1:1,0)),"유지",INDEX(전체_전일자!1:1048576,MATCH(C22,전체_전일자!B:B,0),MATCH("등급",전체_전일자!1:1,0))&" → "&I22),"") | L22: =IFERROR(D22-INDEX(전체_전일자!1:1048576,MATCH(C22,전체_전일자!B:B,0),MATCH("종합스코어",전체_전일자!1:1,0)),"") | M22: =IFERROR(E22-INDEX(전체_전일자!1:1048576,MATCH(C22,전체_전일자!B:B,0),MATCH("모멘텀스코어",전체_전일자!1:1,0)),"") | N22: =IFERROR(F22-INDEX(전체_전일자!1:1048576,MATCH(C22,전체_전일자!B:B,0),MATCH("수급스코어",전체_전일자!1:1,0)),"") | O22: =IFERROR(G22-INDEX(전체_전일자!1:1048576,MATCH(C22,전체_전일자!B:B,0),MATCH("거래량스코어",전체_전일자!1:1,0)),"")
B23: 12 | C23: 시프트업 | D23: 63.6 | E23: 79.4 | F23: 45.8 | G23: 84.4 | H23: 48.93134 | I23: C | K23: =IFERROR(IF(I23=INDEX(전체_전일자!1:1048576,MATCH(C23,전체_전일자!B:B,0),MATCH("등급",전체_전일자!1:1,0)),"유지",INDEX(전체_전일자!1:1048576,MATCH(C23,전체_전일자!B:B,0),MATCH("등급",전체_전일자!1:1,0))&" → "&I23),"") | L23: =IFERROR(D23-INDEX(전체_전일자!1:1048576,MATCH(C23,전체_전일자!B:B,0),MATCH("종합스코어",전체_전일자!1:1,0)),"") | M23: =IFERROR(E23-INDEX(전체_전일자!1:1048576,MATCH(C23,전체_전일자!B:B,0),MATCH("모멘텀스코어",전체_전일자!1:1,0)),"") | N23: =IFERROR(F23-INDEX(전체_전일자!1:1048576,MATCH(C23,전체_전일자!B:B,0),MATCH("수급스코어",전체_전일자!1:1,0)),"") | O23: =IFERROR(G23-INDEX(전체_전일자!1:1048576,MATCH(C23,전체_전일자!B:B,0),MATCH("거래량스코어",전체_전일자!1:1,0)),"")
B24: 13 | C24: 아이에스티이 | D24: 63.6 | E24: 76.8 | F24: 64.3 | G24: 42.2 | H24: 54.358427 | I24: C | K24: =IFERROR(IF(I24=INDEX(전체_전일자!1:1048576,MATCH(C24,전체_전일자!B:B,0),MATCH("등급",전체_전일자!1:1,0)),"유지",INDEX(전체_전일자!1:1048576,MATCH(C24,전체_전일자!B:B,0),MATCH("등급",전체_전일자!1:1,0))&" → "&I24),"") | L24: =IFERROR(D24-INDEX(전체_전일자!1:1048576,MATCH(C24,전체_전일자!B:B,0),MATCH("종합스코어",전체_전일자!1:1,0)),"") | M24: =IFERROR(E24-INDEX(전체_전일자!1:1048576,MATCH(C24,전체_전일자!B:B,0),MATCH("모멘텀스코어",전체_전일자!1:1,0)),"") | N24: =IFERROR(F24-INDEX(전체_전일자!1:1048576,MATCH(C24,전체_전일자!B:B,0),MATCH("수급스코어",전체_전일자!1:1,0)),"") | O24: =IFERROR(G24-INDEX(전체_전일자!1:1048576,MATCH(C24,전체_전일자!B:B,0),MATCH("거래량스코어",전체_전일자!1:1,0)),"")
B25: 14 | C25: 아이씨티케이 | D25: 62 | E25: 53.9 | F25: 84.3 | G25: 18.5 | H25: 54.393106 | I25: C | K25: =IFERROR(IF(I25=INDEX(전체_전일자!1:1048576,MATCH(C25,전체_전일자!B:B,0),MATCH("등급",전체_전일자!1:1,0)),"유지",INDEX(전체_전일자!1:1048576,MATCH(C25,전체_전일자!B:B,0),MATCH("등급",전체_전일자!1:1,0))&" → "&I25),"") | L25: =IFERROR(D25-INDEX(전체_전일자!1:1048576,MATCH(C25,전체_전일자!B:B,0),MATCH("종합스코어",전체_전일자!1:1,0)),"") | M25: =IFERROR(E25-INDEX(전체_전일자!1:1048576,MATCH(C25,전체_전일자!B:B,0),MATCH("모멘텀스코어",전체_전일자!1:1,0)),"") | N25: =IFERROR(F25-INDEX(전체_전일자!1:1048576,MATCH(C25,전체_전일자!B:B,0),MATCH("수급스코어",전체_전일자!1:1,0)),"") | O25: =IFERROR(G25-INDEX(전체_전일자!1:1048576,MATCH(C25,전체_전일자!B:B,0),MATCH("거래량스코어",전체_전일자!1:1,0)),"")
... B50: 39 | C50: HEM파마 | D50: 53.1 | E50: 61.3 | F50: 42.5 | G50: 67.4 | H50: 35.28453 | I50: C | K50: =IFERROR(IF(I50=INDEX(전체_전일자!1:1048576,MATCH(C50,전체_전일자!B:B,0),MATCH("등급",전체_전일자!1:1,0)),"유지",INDEX(전체_전일자!1:1048576,MATCH(C50,전체_전일자!B:B,0),MATCH("등급",전체_전일자!1:1,0))&" → "&I50),"") | L50: =IFERROR(D50-INDEX(전체_전일자!1:1048576,MATCH(C50,전체_전일자!B:B,0),MATCH("종합스코어",전체_전일자!1:1,0)),"") | M50: =IFERROR(E50-INDEX(전체_전일자!1:1048576,MATCH(C50,전체_전일자!B:B,0),MATCH("모멘텀스코어",전체_전일자!1:1,0)),"") | N50: =IFERROR(F50-INDEX(전체_전일자!1:1048576,MATCH(C50,전체_전일자!B:B,0),MATCH("수급스코어",전체_전일자!1:1,0)),"") | O50: =IFERROR(G50-INDEX(전체_전일자!1:1048576,MATCH(C50,전체_전일자!B:B,0),MATCH("거래량스코어",전체_전일자!1:1,0)),"")
B51: 40 | C51: 대진첨단소재 | D51: 53 | E51: 52.7 | F51: 54.4 | G51: 50 | H51: - | I51: C | K51: =IFERROR(IF(I51=INDEX(전체_전일자!1:1048576,MATCH(C51,전체_전일자!B:B,0),MATCH("등급",전체_전일자!1:1,0)),"유지",INDEX(전체_전일자!1:1048576,MATCH(C51,전체_전일자!B:B,0),MATCH("등급",전체_전일자!1:1,0))&" → "&I51),"") | L51: =IFERROR(D51-INDEX(전체_전일자!1:1048576,MATCH(C51,전체_전일자!B:B,0),MATCH("종합스코어",전체_전일자!1:1,0)),"") | M51: =IFERROR(E51-INDEX(전체_전일자!1:1048576,MATCH(C51,전체_전일자!B:B,0),MATCH("모멘텀스코어",전체_전일자!1:1,0)),"") | N51: =IFERROR(F51-INDEX(전체_전일자!1:1048576,MATCH(C51,전체_전일자!B:B,0),MATCH("수급스코어",전체_전일자!1:1,0)),"") | O51: =IFERROR(G51-INDEX(전체_전일자!1:1048576,MATCH(C51,전체_전일자!B:B,0),MATCH("거래량스코어",전체_전일자!1:1,0)),"")
B52: 41 | C52: 와이즈넛 | D52: 52 | E52: 46.2 | F52: 42 | G52: 85.9 | H52: 29.416205 | I52: C | K52: =IFERROR(IF(I52=INDEX(전체_전일자!1:1048576,MATCH(C52,전체_전일자!B:B,0),MATCH("등급",전체_전일자!1:1,0)),"유지",INDEX(전체_전일자!1:1048576,MATCH(C52,전체_전일자!B:B,0),MATCH("등급",전체_전일자!1:1,0))&" → "&I52),"") | L52: =IFERROR(D52-INDEX(전체_전일자!1:1048576,MATCH(C52,전체_전일자!B:B,0),MATCH("종합스코어",전체_전일자!1:1,0)),"") | M52: =IFERROR(E52-INDEX(전체_전일자!1:1048576,MATCH(C52,전체_전일자!B:B,0),MATCH("모멘텀스코어",전체_전일자!1:1,0)),"") | N52: =IFERROR(F52-INDEX(전체_전일자!1:1048576,MATCH(C52,전체_전일자!B:B,0),MATCH("수급스코어",전체_전일자!1:1,0)),"") | O52: =IFERROR(G52-INDEX(전체_전일자!1:1048576,MATCH(C52,전체_전일자!B:B,0),MATCH("거래량스코어",전체_전일자!1:1,0)),"")
B53: 42 | C53: 뉴엔AI | D53: 51.8 | E53: 25.3 | F53: 51.9 | G53: 91.1 | H53: 26.074429 | I53: C | K53: =IFERROR(IF(I53=INDEX(전체_전일자!1:1048576,MATCH(C53,전체_전일자!B:B,0),MATCH("등급",전체_전일자!1:1,0)),"유지",INDEX(전체_전일자!1:1048576,MATCH(C53,전체_전일자!B:B,0),MATCH("등급",전체_전일자!1:1,0))&" → "&I53),"") | L53: =IFERROR(D53-INDEX(전체_전일자!1:1048576,MATCH(C53,전체_전일자!B:B,0),MATCH("종합스코어",전체_전일자!1:1,0)),"") | M53: =IFERROR(E53-INDEX(전체_전일자!1:1048576,MATCH(C53,전체_전일자!B:B,0),MATCH("모멘텀스코어",전체_전일자!1:1,0)),"") | N53: =IFERROR(F53-INDEX(전체_전일자!1:1048576,MATCH(C53,전체_전일자!B:B,0),MATCH("수급스코어",전체_전일자!1:1,0)),"") | O53: =IFERROR(G53-INDEX(전체_전일자!1:1048576,MATCH(C53,전체_전일자!B:B,0),MATCH("거래량스코어",전체_전일자!1:1,0)),"")
B54: 43 | C54: 엔젤로보틱스 | D54: 51.4 | E54: 44.5 | F54: 50 | G54: 65.2 | H54: 46.452636 | I54: C | K54: =IFERROR(IF(I54=INDEX(전체_전일자!1:1048576,MATCH(C54,전체_전일자!B:B,0),MATCH("등급",전체_전일자!1:1,0)),"유지",INDEX(전체_전일자!1:1048576,MATCH(C54,전체_전일자!B:B,0),MATCH("등급",전체_전일자!1:1,0))&" → "&I54),"") | L54: =IFERROR(D54-INDEX(전체_전일자!1:1048576,MATCH(C54,전체_전일자!B:B,0),MATCH("종합스코어",전체_전일자!1:1,0)),"") | M54: =IFERROR(E54-INDEX(전체_전일자!1:1048576,MATCH(C54,전체_전일자!B:B,0),MATCH("모멘텀스코어",전체_전일자!1:1,0)),"") | N54: =IFERROR(F54-INDEX(전체_전일자!1:1048576,MATCH(C54,전체_전일자!B:B,0),MATCH("수급스코어",전체_전일자!1:1,0)),"") | O54: =IFERROR(G54-INDEX(전체_전일자!1:1048576,MATCH(C54,전체_전일자!B:B,0),MATCH("거래량스코어",전체_전일자!1:1,0)),"")
B55: 44 | C55: 데이원컴퍼니 | D55: 51.3 | E55: 38.8 | F55: 64.2 | G55: 37.8 | H55: 32.814473 | I55: C | K55: =IFERROR(IF(I55=INDEX(전체_전일자!1:1048576,MATCH(C55,전체_전일자!B:B,0),MATCH("등급",전체_전일자!1:1,0)),"유지",INDEX(전체_전일자!1:1048576,MATCH(C55,전체_전일자!B:B,0),MATCH("등급",전체_전일자!1:1,0))&" → "&I55),"") | L55: =IFERROR(D55-INDEX(전체_전일자!1:1048576,MATCH(C55,전체_전일자!B:B,0),MATCH("종합스코어",전체_전일자!1:1,0)),"") | M55: =IFERROR(E55-INDEX(전체_전일자!1:1048576,MATCH(C55,전체_전일자!B:B,0),MATCH("모멘텀스코어",전체_전일자!1:1,0)),"") | N55: =IFERROR(F55-INDEX(전체_전일자!1:1048576,MATCH(C55,전체_전일자!B:B,0),MATCH("수급스코어",전체_전일자!1:1,0)),"") | O55: =IFERROR(G55-INDEX(전체_전일자!1:1048576,MATCH(C55,전체_전일자!B:B,0),MATCH("거래량스코어",전체_전일자!1:1,0)),"")
B56: 45 | C56: 이엔셀 | D56: 51.2 | E56: 32.8 | F56: 63.4 | G56: 48.1 | H56: 25.879442 | I56: C | K56: =IFERROR(IF(I56=INDEX(전체_전일자!1:1048576,MATCH(C56,전체_전일자!B:B,0),MATCH("등급",전체_전일자!1:1,0)),"유지",INDEX(전체_전일자!1:1048576,MATCH(C56,전체_전일자!B:B,0),MATCH("등급",전체_전일자!1:1,0))&" → "&I56),"") | L56: =IFERROR(D56-INDEX(전체_전일자!1:1048576,MATCH(C56,전체_전일자!B:B,0),MATCH("종합스코어",전체_전일자!1:1,0)),"") | M56: =IFERROR(E56-INDEX(전체_전일자!1:1048576,MATCH(C56,전체_전일자!B:B,0),MATCH("모멘텀스코어",전체_전일자!1:1,0)),"") | N56: =IFERROR(F56-INDEX(전체_전일자!1:1048576,MATCH(C56,전체_전일자!B:B,0),MATCH("수급스코어",전체_전일자!1:1,0)),"") | O56: =IFERROR(G56-INDEX(전체_전일자!1:1048576,MATCH(C56,전체_전일자!B:B,0),MATCH("거래량스코어",전체_전일자!1:1,0)),"")
B57: 46 | C57: 신한글로벌액티브리츠 | D57: 51.1 | E57: 41.1 | F57: 49.3 | G57: 70.4 | H57: 25.0358 | I57: C | K57: =IFERROR(IF(I57=INDEX(전체_전일자!1:1048576,MATCH(C57,전체_전일자!B:B,0),MATCH("등급",전체_전일자!1:1,0)),"유지",INDEX(전체_전일자!1:1048576,MATCH(C57,전체_전일자!B:B,0),MATCH("등급",전체_전일자!1:1,0))&" → "&I57),"") | L57: =IFERROR(D57-INDEX(전체_전일자!1:1048576,MATCH(C57,전체_전일자!B:B,0),MATCH("종합스코어",전체_전일자!1:1,0)),"") | M57: =IFERROR(E57-INDEX(전체_전일자!1:1048576,MATCH(C57,전체_전일자!B:B,0),MATCH("모멘텀스코어",전체_전일자!1:1,0)),"") | N57: =IFERROR(F57-INDEX(전체_전일자!1:1048576,MATCH(C57,전체_전일자!B:B,0),MATCH("수급스코어",전체_전일자!1:1,0)),"") | O57: =IFERROR(G57-INDEX(전체_전일자!1:1048576,MATCH(C57,전체_전일자!B:B,0),MATCH("거래량스코어",전체_전일자!1:1,0)),"")
B58: 47 | C58: 제일엠앤에스 | D58: 50.8 | E58: 52.7 | F58: 50 | G58: 50 | H58: - | I58: C | K58: =IFERROR(IF(I58=INDEX(전체_전일자!1:1048576,MATCH(C58,전체_전일자!B:B,0),MATCH("등급",전체_전일자!1:1,0)),"유지",INDEX(전체_전일자!1:1048576,MATCH(C58,전체_전일자!B:B,0),MATCH("등급",전체_전일자!1:1,0))&" → "&I58),"") | L58: =IFERROR(D58-INDEX(전체_전일자!1:1048576,MATCH(C58,전체_전일자!B:B,0),MATCH("종합스코어",전체_전일자!1:1,0)),"") | M58: =IFERROR(E58-INDEX(전체_전일자!1:1048576,MATCH(C58,전체_전일자!B:B,0),MATCH("모멘텀스코어",전체_전일자!1:1,0)),"") | N58: =IFERROR(F58-INDEX(전체_전일자!1:1048576,MATCH(C58,전체_전일자!B:B,0),MATCH("수급스코어",전체_전일자!1:1,0)),"") | O58: =IFERROR(G58-INDEX(전체_전일자!1:1048576,MATCH(C58,전체_전일자!B:B,0),MATCH("거래량스코어",전체_전일자!1:1,0)),"")
B59: 48 | C59: 쓰리에이로직스 | D59: 50.3 | E59: 47.3 | F59: 39.6 | G59: 81.5 | H59: 35.482766 | I59: C | K59: =IFERROR(IF(I59=INDEX(전체_전일자!1:1048576,MATCH(C59,전체_전일자!B:B,0),MATCH("등급",전체_전일자!1:1,0)),"유지",INDEX(전체_전일자!1:1048576,MATCH(C59,전체_전일자!B:B,0),MATCH("등급",전체_전일자!1:1,0))&" → "&I59),"") | L59: =IFERROR(D59-INDEX(전체_전일자!1:1048576,MATCH(C59,전체_전일자!B:B,0),MATCH("종합스코어",전체_전일자!1:1,0)),"") | M59: =IFERROR(E59-INDEX(전체_전일자!1:1048576,MATCH(C59,전체_전일자!B:B,0),MATCH("모멘텀스코어",전체_전일자!1:1,0)),"") | N59: =IFERROR(F59-INDEX(전체_전일자!1:1048576,MATCH(C59,전체_전일자!B:B,0),MATCH("수급스코어",전체_전일자!1:1,0)),"") | O59: =IFERROR(G59-INDEX(전체_전일자!1:1048576,MATCH(C59,전체_전일자!B:B,0),MATCH("거래량스코어",전체_전일자!1:1,0)),"")
B60: 49 | C60: 삼현 | D60: 50.2 | E60: 48.6 | F60: 50 | G60: 53.3 | H60: 40.559012 | I60: C | K60: =IFERROR(IF(I60=INDEX(전체_전일자!1:1048576,MATCH(C60,전체_전일자!B:B,0),MATCH("등급",전체_전일자!1:1,0)),"유지",INDEX(전체_전일자!1:1048576,MATCH(C60,전체_전일자!B:B,0),MATCH("등급",전체_전일자!1:1,0))&" → "&I60),"") | L60: =IFERROR(D60-INDEX(전체_전일자!1:1048576,MATCH(C60,전체_전일자!B:B,0),MATCH("종합스코어",전체_전일자!1:1,0)),"") | M60: =IFERROR(E60-INDEX(전체_전일자!1:1048576,MATCH(C60,전체_전일자!B:B,0),MATCH("모멘텀스코어",전체_전일자!1:1,0)),"") | N60: =IFERROR(F60-INDEX(전체_전일자!1:1048576,MATCH(C60,전체_전일자!B:B,0),MATCH("수급스코어",전체_전일자!1:1,0)),"") | O60: =IFERROR(G60-INDEX(전체_전일자!1:1048576,MATCH(C60,전체_전일자!B:B,0),MATCH("거래량스코어",전체_전일자!1:1,0)),"")

Sheet 추천종목
A1: 코드 | B1: 코드명 | C1: 상장일 | D1: 현재가 | E1: 거래대금(억) | F1: 종합스코어 | G1: 모멘텀스코어 | H1: 수급스코어 | I1: 거래량스코어 | J1: RSI변화량 | K1: RSI(14) | L1: 전일RSI(14) | M1: RVOL(20) | N1: 기관_일간 | O1: 외국인_일간 | P1: 10일선돌파 | Q1: 20일선돌파 | R1: 60일선돌파 | S1: 변동성(30D) | T1: BB폭
A2: A476080 | B2: M83 | D2: 7760 | E2: 19.854038 | F2: 74.3 | G2: 98.1 | H2: 49.8 | I2: 100 | J2: 25 | K2: 65.950345 | L2: 40.922803 | M2: 3.9403885 | N2: 0 | O2: 1.9 | P2: 1 | Q2: 1 | R2: 1 | S2: 8.5578053 | T2: 2914.9675
A3: A347850 | B3: 디앤디파마텍 | D3: 94000 | E3: 1810.2473 | F3: 73.6 | G3: 98.8 | H3: 50 | I3: 94.8 | J3: 11.5 | K3: 59.719538 | L3: 48.212381 | M3: 1.4118697 | P3: 1 | Q3: 1 | R3: 1 | S3: 8.1432137 | T3: 54794.587
A4: A475660 | B4: 에스켐 | D4: 4540 | E4: 1.3223658 | F4: 72 | G4: 90.3 | H4: 54.2 | I4: 88.9 | J4: 14 | K4: 44.206431 | L4: 30.237798 | M4: 1.0115315 | N4: 0 | O4: 4.7 | P4: 1 | Q4: 0 | R4: 0 | S4: 4.761231 | T4: 1193.5312
A5: A473980 | B5: 노머스 | D5: 14000 | E5: 6.33892 | F5: 68.3 | G5: 46.6 | H5: 79.9 | I5: 71.9 | J5: 5.8 | K5: 35.38595 | L5: 29.594919 | M5: 0.67708559 | N5: 34.8 | O5: 23.2 | P5: 0 | Q5: 0 | R5: 0 | S5: 3.4568979 | T5: 5398.5242
A6: A295310 | B6: 에이치브이엠 | D6: 102600 | E6: 274.81307 | F6: 68.3 | G6: 70.5 | H6: 67 | I6: 68.1 | J6: 5.1 | K6: 50.032472 | L6: 44.914819 | M6: 0.62451547 | N6: 64.3 | O6: 71.5 | P6: 0 | Q6: 0 | R6: 1 | S6: 9.5068703 | T6: 51960.487
A7: A279570 | B7: 케이뱅크 | D7: 5590 | E7: 64.3139 | F7: 67.6 | G7: 75.6 | H7: 67.9 | I7: 54.8 | J7: 12.7 | K7: 39.379227 | L7: 26.722328 | M7: 0.5182964 | N7: 188.6 | O7: 56.5 | P7: 1 | Q7: 0 | R7: 0 | S7: 2.2128591 | T7: 853.7003
A8: A457600 | B8: 벡트 | D8: 1611 | E8: 1.6017529 | F8: 65.2 | G8: 52.4 | H8: 60.2 | I8: 97 | J8: -15.7 | K8: 34.928758 | L8: 50.661688 | M8: 2.1299189 | N8: 0.2 | O8: 0.7 | P8: 0 | Q8: 0 | R8: 0 | S8: 3.4730753 | T8: 895.64382
A9: A098070 | B9: 한텍 | D9: 36800 | E9: 41.505984 | F9: 64.5 | G9: 87.6 | H9: 39.7 | I9: 91.9 | J9: 10.6 | K9: 45.700896 | L9: 35.075721 | M9: 1.0710694 | N9: -21.9 | O9: 7.3 | P9: 1 | Q9: 0 | R9: 0 | S9: 3.9205486 | T9: 14878.805
A10: A457370 | B10: 한켐 | D10: 11290 | E10: 68.17252 | F10: 64.3 | G10: 71.5 | H10: 67 | I10: 46.7 | J10: -4.5 | K10: 60.112585 | L10: 64.612652 | M10: 0.43022792 | N10: 9.9 | O10: 145.3 | P10: 1 | Q10: 1 | R10: 1 | S10: 7.5742566 | T10: 6385.1209
A11: A466100 | B11: 클로봇 | D11: 46450 | E11: 221.04115 | F11: 64.2 | G11: 71.5 | H11: 50.2 | I11: 88.1 | J11: 4.9 | K11: 50.165413 | L11: 45.302741 | M11: 1.0114305 | N11: 281.5 | O11: -241.8 | P11: 1 | Q11: 1 | R11: 0 | S11: 4.2630254 | T11: 13252.444
A12: A483650 | B12: 달바글로벌 | D12: 198100 | E12: 517.26882 | F12: 64.1 | G12: 69.5 | H12: 50.7 | I12: 89.6 | J12: 18.5 | K12: 43.867101 | L12: 25.40614 | M12: 1.0269483 | N12: -1546 | O12: 1589.7 | P12: 0 | Q12: 0 | R12: 1 | S12: 4.6744229 | T12: 74619.357
A13: A212710 | B13: 아이에스티이 | D13: 11510 | E13: 20.847718 | F13: 63.6 | G13: 76.8 | H13: 64.3 | I13: 42.2 | J13: -14 | K13: 54.358427 | L13: 68.363385 | M13: 0.40606491 | N13: 2.4 | O13: 30.1 | P13: 0 | Q13: 1 | R13: 1 | S13: 6.3058541 | T13: 4249.0688
A14: A462870 | B14: 시프트업 | D14: 30450 | E14: 23.668176 | F14: 63.6 | G14: 79.4 | H14: 45.8 | I14: 84.4 | J14: 8.3 | K14: 48.93134 | L14: 40.612545 | M14: 0.90146386 | N14: 80.7 | O14: -26.3 | P14: 1 | Q14: 1 | R14: 0 | S14: 2.3150377 | T14: 5017.5586
A15: A456010 | B15: 아이씨티케이 | D15: 28150 | E15: 173.5684 | F15: 62 | G15: 53.9 | H15: 84.3 | I15: 18.5 | J15: -1.4 | K15: 54.393106 | L15: 55.76564 | M15: 0.28445863 | N15: 12.1 | O15: 319.6 | P15: 0 | Q15: 1 | R15: 1 | S15: 9.1631452 | T15: 19888.898
... A31: A160190 | B31: 하이젠알앤엠 | D31: 30450 | E31: 40.233889 | F31: 55.5 | G31: 36.1 | H31: 68.6 | I31: 51.9 | J31: 13.8 | K31: 33.026318 | L31: 19.176734 | M31: 0.4854939 | N31: 116.4 | O31: -6.4 | P31: 0 | Q31: 0 | R31: 0 | S31: 4.5839128 | T31: 18045.976
A32: A309710 | B32: 아이티켐 | D32: 21000 | F32: 55.4 | G32: 60.8 | H32: 54.4 | I32: 50 | K32: 48.751956 | N32: 0 | O32: 0 | P32: 0 | Q32: 0 | R32: 0 | S32: 0 | T32: 0
A33: A464280 | B33: 티디에스팜 | D33: 7010 | E33: 2.0935365 | F33: 55 | G33: 40 | H33: 53.7 | I33: 80.7 | J33: 8.4 | K33: 30.177758 | L33: 21.814804 | M33: 0.83897873 | N33: 0 | O33: 0.1 | P33: 0 | Q33: 0 | R33: 0 | S33: 3.0007649 | T33: 2069.9952
A34: A486990 | B34: 노타 | D34: 39100 | E34: 570.7384 | F34: 54.6 | G34: 98 | H34: 11.2 | I34: 97.8 | J34: 11.9 | K34: 60.281059 | L34: 48.416358 | M34: 2.246689 | N34: -143.8 | O34: -73.7 | P34: 1 | Q34: 1 | R34: 1 | S34: 7.4864593 | T34: 15441.881
A35: A031210 | B35: 서울보증보험 | D35: 43450 | E35: 21.771491 | F35: 54.6 | G35: 57.7 | H35: 49.1 | I35: 63.7 | J35: 8.3 | K35: 37.130829 | L35: 28.819263 | M35: 0.59549425 | N35: -121.3 | O35: 164.1 | P35: 0 | Q35: 0 | R35: 0 | S35: 2.2897461 | T35: 5308.9398
A36: A382150 | B36: 온코크로스 | D36: 5350 | E36: 4.24255 | F36: 54.5 | G36: 21.3 | H36: 64.5 | I36: 79.3 | J36: 11.2 | K36: 28.042048 | L36: 16.798042 | M36: 0.78327679 | N36: 0.1 | O36: 9 | P36: 0 | Q36: 0 | R36: 0 | S36: 4.7969425 | T36: 3033.4445
A37: A234030 | B37: 싸이닉솔루션 | D37: 4735 | E37: 5.8319101 | F37: 53.4 | G37: 27.2 | H37: 65.6 | I37: 62.2 | J37: -0.7 | K37: 24.553169 | L37: 25.272101 | M37: 0.5801331 | N37: -3.7 | O37: 18.9 | P37: 0 | Q37: 0 | R37: 0 | S37: 3.2796983 | T37: 3189.9215
A38: A468530 | B38: 프로티나 | D38: 37500 | E38: 21.2535 | F38: 53.3 | G38: 42 | H38: 52 | I38: 73.3 | J38: 10.9 | K38: 26.424076 | L38: 15.521495 | M38: 0.6899549 | N38: -90 | O38: 151.2 | P38: 0 | Q38: 0 | R38: 0 | S38: 4.2124554 | T38: 21901.252
A39: A064400 | B39: LG씨엔에스 | D39: 126400 | E39: 4203.9932 | F39: 53.2 | G39: 71.5 | H39: 30.7 | I39: 82.2 | J39: -9.2 | K39: 68.984488 | L39: 78.150327 | M39: 0.84817437 | N39: -1246.3 | O39: -7420.8 | P39: 1 | Q39: 1 | R39: 1 | S39: 9.0699357 | T39: 92024.198
A40: A376270 | B40: HEM파마 | D40: 49250 | E40: 11.23491 | F40: 53.1 | G40: 61.3 | H40: 42.5 | I40: 67.4 | J40: 12.1 | K40: 35.28453 | L40: 23.162993 | M40: 0.62406644 | N40: 40.4 | O40: -12.6 | P40: 0 | Q40: 0 | R40: 0 | S40: 5.0832422 | T40: 32413.993
A41: A393970 | B41: 대진첨단소재 | D41: 2825 | F41: 53 | G41: 52.7 | H41: 54.4 | I41: 50 | N41: 0 | O41: 0 | P41: 0 | Q41: 0 | R41: 0 | S41: 0 | T41: 0
A42: A096250 | B42: 와이즈넛 | D42: 7890 | E42: 5.0349246 | F42: 52 | G42: 46.2 | H42: 42 | I42: 85.9 | J42: 16.3 | K42: 29.416205 | L42: 13.110655 | M42: 0.91908498 | N42: -4.1 | O42: 15.4 | P42: 0 | Q42: 0 | R42: 0 | S42: 2.8601645 | T42: 3237.5195
A43: A463020 | B43: 뉴엔AI | D43: 8820 | E43: 8.7221862 | F43: 51.8 | G43: 25.3 | H43: 51.9 | I43: 91.1 | J43: 2.4 | K43: 26.074429 | L43: 23.710033 | M43: 1.065199 | N43: -2 | O43: 25.3 | P43: 0 | Q43: 0 | R43: 0 | S43: 3.9081253 | T43: 7318.1013
A44: A455900 | B44: 엔젤로보틱스 | D44: 27200 | E44: 27.34008 | F44: 51.4 | G44: 44.5 | H44: 50 | I44: 65.2 | J44: 3.7 | K44: 46.452636 | L44: 42.794451 | M44: 0.60900576 | P44: 0 | Q44: 0 | R44: 0 | S44: 5.5869587 | T44: 6623.3638
A45: A373160 | B45: 데이원컴퍼니 | D45: 3800 | E45: 0.45809 | F45: 51.3 | G45: 38.8 | H45: 64.2 | I45: 37.8 | J45: 13.7 | K45: 32.814473 | L45: 19.1191 | M45: 0.38008967 | N45: 3.1 | O45: 2.2 | P45: 0 | Q45: 0 | R45: 0 | S45: 4.0312447 | T45: 1398.9334
A46: A456070 | B46: 이엔셀 | D46: 9780 | E46: 4.988289 | F46: 51.2 | G46: 32.8 | H46: 63.4 | I46: 48.1 | J46: 10 | K46: 25.879442 | L46: 15.858352 | M46: 0.43691632 | N46: 0.8 | O46: 14.5 | P46: 0 | Q46: 0 | R46: 0 | S46: 3.6627661 | T46: 6198.6471
A47: A481850 | B47: 신한글로벌액티브리츠 | D47: 923 | E47: 0.59473505 | F47: 51.1 | G47: 41.1 | H47: 49.3 | I47: 70.4 | J47: 8.5 | K47: 25.0358 | L47: 16.575252 | M47: 0.63779885 | N47: 0.6 | O47: -0.6 | P47: 0 | Q47: 0 | R47: 0 | S47: 1.9202047 | T47: 234.5855
A48: A412540 | B48: 제일엠앤에스 | D48: 3935 | F48: 50.8 | G48: 52.7 | H48: 50 | I48: 50 | P48: 0 | Q48: 0 | R48: 0 | S48: 0 | T48: 0
A49: A177900 | B49: 쓰리에이로직스 | D49: 5680 | E49: 7.7660368 | F49: 50.3 | G49: 47.3 | H49: 39.6 | I49: 81.5 | J49: -11.7 | K49: 35.482766 | L49: 47.204038 | M49: 0.84229501 | N49: -2.2 | O49: -4.8 | P49: 0 | Q49: 0 | R49: 0 | S49: 4.6090384 | T49: 2514.8284
A50: A437730 | B50: 삼현 | D50: 47900 | E50: 96.388691 | F50: 50.2 | G50: 48.6 | H50: 50 | I50: 53.3 | J50: 8 | K50: 40.559012 | L50: 32.560339 | M50: 0.51348862 | P50: 0 | Q50: 0 | R50: 0 | S50: 5.1966304 | T50: 13268.578
A51: A217590 | B51: 티엠씨 | D51: 19850 | E51: 52.032408 | F51: 49.8 | G51: 46.3 | H51: 51.9 | I51: 49.6 | J51: -2.4 | K51: 35.962839 | L51: 38.333512 | M51: 0.46065251 | N51: -112.9 | O51: 100.1 | P51: 0 | Q51: 0 | R51: 0 | S51: 7.618029 | T51: 16250.445

Sheet 전체
A1: 코드 | B1: 코드명 | C1: 상장일 | D1: days_since_ipo | E1: 기관_일간 | F1: 기관_5일 | G1: 기관_20일 | H1: 외국인_일간 | I1: 외국인_5일 | J1: 외국인_20일 | K1: 현재가 | L1: 거래량 | M1: 거래대금(억) | N1: 20일평균거래량 | O1: RVOL(20) | P1: 변동성(30D) | Q1: RSI(14) | R1: 전일RSI(14) | S1: RSI변화량 | T1: 1일수익률(%) | U1: 20일수익률(%) | V1: 10일이평 | W1: 20일이평 | X1: 60일이평 | Y1: 10일선돌파 | Z1: 20일선돌파 | AA1: 60일선돌파 | AB1: BB폭 | AC1: 모멘텀스코어 | AD1: 수급스코어 | AE1: 거래량스코어 | AF1: 종합스코어 | AG1: 등급
A2: A458350 | B2: 에스팀 | E2: 0.2 | F2: -3.7 | G2: -7.1 | H2: 10.5 | I2: 22 | J2: 28.1 | K2: 5590 | L2: 16455 | M2: 0.9198345 | N2: 66784.85 | O2: 0.24638822 | P2: 2.5403041 | Q2: 8.4920043 | R2: 5.5523594 | S2: 2.9 | T2: 1.084991 | U2: -38.163717 | V2: 6232 | W2: 7077 | X2: 10112.833 | Y2: 0 | Z2: 0 | AA2: 0 | AB2: 4211.545 | AC2: 24.5 | AD2: 60.8 | AE2: 16.3 | AF2: 41 | AG2: D
A3: A279570 | B3: 케이뱅크 | E3: 188.6 | F3: 1261.1 | G3: 2414.4 | H3: 56.5 | I3: -172.6 | J3: -1422.9 | K3: 5590 | L3: 1150517 | M3: 64.3139 | N3: 2219805.1 | O3: 0.5182964 | P3: 2.2128591 | Q3: 39.379227 | R3: 26.722328 | S3: 12.7 | T3: 0 | U3: -11.128776 | V3: 5569 | W3: 5626.5 | X3: 6164.1667 | Y3: 1 | Z3: 0 | AA3: 0 | AB3: 853.7003 | AC3: 75.6 | AD3: 67.9 | AE3: 54.8 | AF3: 67.6 | AG3: B
A4: A490470 | B4: 세미파이브 | E4: -4.9 | F4: -301.2 | G4: -1058 | H4: -20.1 | I4: -1802.6 | J4: -1273.4 | K4: 38100 | L4: 882203 | M4: 336.11934 | N4: 1236360.4 | O4: 0.71354838 | P4: 6.883819 | Q4: 49.74338 | R4: 28.176565 | S4: 21.6 | T4: -3.5443038 | U4: -21.92623 | V4: 38490 | W4: 38847.5 | X4: 33506.667 | Y4: 0 | Z4: 0 | AA4: 1 | AB4: 11641.934 | AC4: 40.3 | AD4: 12.2 | AE4: 74.1 | AF4: 33 | AG4: D
A5: A491000 | B5: 리브스메드 | E5: -124.2 | F5: -797.1 | G5: -1957.8 | H5: 130.3 | I5: -2070.8 | J5: 2326.7 | K5: 49400 | L5: 179150 | M5: 88.5001 | N5: 420450.45 | O5: 0.42609064 | P5: 6.3325383 | Q5: 35.120554 | R5: 25.146179 | S5: 10 | T5: 3.0239833 | U5: -29.226361 | V5: 59575 | W5: 61687.5 | X5: 67859.167 | Y5: 0 | Z5: 0 | AA5: 0 | AB5: 30419.237 | AC5: 50.3 | AD5: 33.2 | AE5: 45.9 | AF5: 40.9 | AG5: D
A6: A476830 | B6: 알지노믹스 | E6: -557.6 | F6: -1867.9 | G6: -5921.3 | H6: 941 | I6: 1190 | J6: 8876.5 | K6: 110000 | L6: 231128 | M6: 254.2408 | N6: 299938.8 | O6: 0.77058387 | P6: 4.7133699 | Q6: 28.103637 | R6: 17.720038 | S6: 10.4 | T6: -0.81154193 | U6: -36.962751 | V6: 128640 | W6: 142665 | X6: 177491.67 | Y6: 0 | Z6: 0 | AA6: 0 | AB6: 77209.574 | AC6: 22.8 | AD6: 50.5 | AE6: 77.8 | AF6: 47.7 | AG6: D
A7: A478340 | B7: 나라스페이스테크놀로지 | E7: -8.5 | F7: -9.5 | G7: -183 | H7: 137.8 | I7: -29 | J7: 75 | K7: 23400 | L7: 118111 | M7: 27.637974 | N7: 312140.85 | O7: 0.37839008 | P7: 5.616511 | Q7: 34.491198 | R7: 25.961415 | S7: 8.5 | T7: 5.6433409 | U7: -31.47877 | V7: 26605 | W7: 28842.5 | X7: 35685 | Y7: 0 | Z7: 0 | AA7: 0 | AB7: 13172.423 | AC7: 50.2 | AD7: 49.1 | AE7: 37 | AF7: 47 | AG7: D
A8: A217590 | B8: 티엠씨 | E8: -112.9 | F8: -250.3 | G8: -148.4 | H8: 100.1 | I8: 215.5 | J8: 368 | K8: 19850 | L8: 262128 | M8: 52.032408 | N8: 569036.3 | O8: 0.46065251 | P8: 7.618029 | Q8: 35.962839 | R8: 38.333512 | S8: -2.4 | T8: 4.7493404 | U8: -35.864297 | V8: 23950 | W8: 26417.5 | X8: 24650 | Y8: 0 | Z8: 0 | AA8: 0 | AB8: 16250.445 | AC8: 46.3 | AD8: 51.9 | AE8: 49.6 | AF8: 49.8 | AG8: D
A9: A464490 | B9: 쿼드메디슨 | E9: -1.8 | F9: 13.1 | G9: -23.7 | H9: 13.5 | I9: 58.8 | J9: 162.1 | K9: 8210 | L9: 55389 | M9: 4.5474369 | N9: 109949.95 | O9: 0.50376558 | P9: 3.0455665 | Q9: 17.772058 | R9: 6.8982911 | S9: 10.9 | T9: -2.3781213 | U9: -36.748844 | V9: 9384 | W9: 10377.5 | X9: 12845.167 | Y9: 0 | Z9: 0 | AA9: 0 | AB9: 4945.2902 | AC9: 11.1 | AD9: 62.8 | AE9: 52.6 | AF9: 45.2 | AG9: D
A10: A261520 | B10: 이지스 | E10: 0 | F10: -0.1 | G10: -52.9 | H10: 9.5 | I10: 23.9 | J10: 53.9 | K10: 4975 | L10: 32529 | M10: 1.6183178 | N10: 73545.9 | O10: 0.44229522 | P10: 3.0055473 | Q10: 21.732463 | R10: 10.421199 | S10: 11.3 | T10: 1.0152284 | U10: -36.217949 | V10: 5501 | W10: 6121 | X10: 7748.3333 | Y10: 0 | Z10: 0 | AA10: 0 | AB10: 3110.8137 | AC10: 27 | AD10: 58.3 | AE10: 48.9 | AF10: 47 | AG10: D
A11: A950250 | B11: 테라뷰 | E11: -0.1 | F11: -0.1 | G11: -30.7 | H11: 82.7 | I11: -78.9 | J11: -47.9 | K11: 3540 | L11: 442471 | M11: 15.663473 | N11: 959401.55 | O11: 0.46119479 | P11: 4.0061721 | Q11: 21.718503 | R11: 9.8048533 | S11: 11.9 | T11: 3.8123167 | U11: -46.766917 | V11: 4081.5 | W11: 4772.5 | X11: 6407.6667 | Y11: 0 | Z11: 0 | AA11: 0 | AB11: 3620.9188 | AC11: 28 | AD11: 49.8 | AE11: 50.4 | AF11: 43.4 | AG11: D
A12: A488900 | B12: 비츠로넥스텍 | E12: 0.1 | F12: -55.2 | G12: -441.8 | H12: 39.2 | I12: 43.5 | J12: 171.2 | K12: 11900 | L12: 94640 | M12: 11.26216 | N12: 137889 | O12: 0.68634916 | P12: 3.8624689 | Q12: 24.702113 | R12: 16.278417 | S12: 8.4 | T12: -1.2448133 | U12: -38.691396 | V12: 14056 | W12: 15923.5 | X12: 17755 | Y12: 0 | Z12: 0 | AA12: 0 | AB12: 9289.2266 | AC12: 16 | AD12: 58.7 | AE12: 72.6 | AF12: 48.7 | AG12: D
A13: A388210 | B13: 씨엠티엑스 | E13: -209.4 | F13: -1003.7 | G13: -4665.9 | H13: 48.5 | I13: 872.8 | J13: 1325.7 | K13: 106000 | L13: 80074 | M13: 84.87844 | N13: 126245.2 | O13: 0.63427362 | P13: 4.0865939 | Q13: 36.389936 | R13: 30.747954 | S13: 5.6 | T13: -2.0332717 | U13: -24.393723 | V13: 113270 | W13: 120415 | X13: 133206.67 | Y13: 0 | Z13: 0 | AA13: 0 | AB13: 39935.796 | AC13: 37.3 | AD13: 46.2 | AE13: 69.6 | AF13: 48.2 | AG13: D
... A24: A456160 | B24: 지투지바이오 | E24: 39.8 | F24: -651.8 | G24: -558.2 | H24: 178.8 | I24: -196 | J24: 690.5 | K24: 53500 | L24: 184821 | M24: 98.879235 | N24: 287970.95 | O24: 0.64180432 | P24: 4.826872 | Q24: 29.524383 | R24: 12.064757 | S24: 17.5 | T24: -0.37243948 | U24: -37.206573 | V24: 59040 | W24: 65005 | X24: 75601.667 | Y24: 0 | Z24: 0 | AA24: 0 | AB24: 31889.408 | AC24: 24.5 | AD24: 53.7 | AE24: 71.1 | AF24: 48.4 | AG24: D
A25: A309710 | B25: 아이티켐 | E25: 0 | F25: 0 | G25: 0 | H25: 0 | I25: 0 | J25: 0 | K25: 21000 | L25: 0 | N25: 0 | P25: 0 | Q25: 48.751956 | T25: 0 | U25: 0 | V25: 21000 | W25: 21000 | X25: 24323.333 | Y25: 0 | Z25: 0 | AA25: 0 | AB25: 0 | AC25: 60.8 | AD25: 54.4 | AE25: 50 | AF25: 55.4 | AG25: C
A26: A439260 | B26: 대한조선 | E26: 16.5 | F26: -310.3 | G26: -1463.7 | H26: -14.9 | I26: 48.3 | J26: -976.1 | K26: 62000 | L26: 70412 | M26: 43.65544 | N26: 123542.2 | O26: 0.5699429 | P26: 2.5745637 | Q26: 25.930481 | R26: 10.00953 | S26: 15.9 | T26: 0.9771987 | U26: -30.726257 | V26: 65400 | W26: 70845 | X26: 84750 | Y26: 0 | Z26: 0 | AA26: 0 | AB26: 31012.52 | AC26: 36.6 | AD26: 36.5 | AE26: 61.5 | AF26: 41.5 | AG26: D
A27: A468530 | B27: 프로티나 | E27: -90 | F27: -398 | G27: -633.8 | H27: 151.2 | I27: 578.8 | J27: 1346.9 | K27: 37500 | L27: 56676 | M27: 21.2535 | N27: 82144.5 | O27: 0.6899549 | P27: 4.2124554 | Q27: 26.424076 | R27: 15.521495 | S27: 10.9 | T27: 4.0221914 | U27: -32.065217 | V27: 41515 | W27: 45720 | X27: 60701.667 | Y27: 0 | Z27: 0 | AA27: 0 | AB27: 21901.252 | AC27: 42 | AD27: 52 | AE27: 73.3 | AF27: 53.3 | AG27: C
A28: A475230 | B28: 엔알비 | E28: 17.7 | F28: 55.6 | G28: 40.4 | H28: 23.1 | I28: 53.9 | J28: 426.1 | K28: 11870 | L28: 41182 | M28: 4.8883034 | N28: 139724.45 | O28: 0.29473725 | P28: 4.1186128 | Q28: 22.27623 | R28: 17.640194 | S28: 4.6 | T28: -3.5743298 | U28: -37.029178 | V28: 13866 | W28: 15369.5 | X28: 19521.167 | Y28: 0 | Z28: 0 | AA28: 0 | AB28: 7936.0335 | AC28: 8.7 | AD28: 82.4 | AE28: 20.7 | AF28: 48 | AG28: D
A29: A380550 | B29: 뉴로핏 | E29: -5.5 | F29: -12.3 | G29: -72.8 | H29: 75 | I29: 191.6 | J29: 213.9 | K29: 13310 | L29: 157333 | M29: 20.941022 | N29: 479759.6 | O29: 0.32794133 | P29: 4.1436218 | Q29: 27.681957 | R29: 20.055471 | S29: 7.6 | T29: 0.52870091 | U29: -33.216257 | V29: 15358 | W29: 16747 | X29: 19825.833 | Y29: 0 | Z29: 0 | AA29: 0 | AB29: 7568.1449 | AC29: 32.9 | AD29: 59.3 | AE29: 28.1 | AF29: 45.1 | AG29: D
A30: A484120 | B30: 도우인시스 | E30: -2.1 | F30: -4.2 | G30: -10 | H30: 5.1 | I30: -30.2 | J30: -53.2 | K30: 16840 | L30: 15022 | M30: 2.5297048 | N30: 28505.8 | O30: 0.52698047 | P30: 3.7868111 | Q30: 32.446241 | R30: 23.204994 | S30: 9.2 | T30: -2.7713626 | U30: -27.099567 | V30: 18521 | W30: 20358 | X30: 20613.833 | Y30: 0 | Z30: 0 | AA30: 0 | AB30: 8934.7256 | AC30: 29.4 | AD30: 40.1 | AE30: 56.3 | AF30: 40.1 | AG30: D
A31: A331740 | B31: 아우토크립트 | E31: -8.4 | F31: 117.8 | G31: -120.5 | H31: -40.6 | I31: -96.7 | J31: -131.3 | K31: 10580 | L31: 219498 | M31: 23.222888 | N31: 108080.6 | O31: 2.0308733 | P31: 5.3353652 | Q31: 33.681263 | R31: 34.863772 | S31: -1.2 | T31: -12.921811 | U31: -28.561783 | V31: 12247 | W31: 12699 | X31: 15147.833 | Y31: 0 | Z31: 0 | AA31: 0 | AB31: 4306.1943 | AC31: 24.9 | AD31: 32.2 | AE31: 96.3 | AF31: 42.8 | AG31: D
A32: A234030 | B32: 싸이닉솔루션 | E32: -3.7 | F32: 1 | G32: 4.2 | H32: 18.9 | I32: 65.3 | J32: 50.5 | K32: 4735 | L32: 123166 | M32: 5.8319101 | N32: 212306.45 | O32: 0.5801331 | P32: 3.2796983 | Q32: 24.553169 | R32: 25.272101 | S32: -0.7 | T32: 0.42417815 | U32: -35.840108 | V32: 5242.5 | W32: 5844.75 | X32: 6665.4167 | Y32: 0 | Z32: 0 | AA32: 0 | AB32: 3189.9215 | AC32: 27.2 | AD32: 65.6 | AE32: 62.2 | AF32: 53.4 | AG32: C
A33: A463020 | B33: 뉴엔AI | E33: -2 | F33: -11.4 | G33: -29 | H33: 25.3 | I33: 16 | J33: -7.2 | K33: 8820 | L33: 98891 | M33: 8.7221862 | N33: 92838.05 | O33: 1.065199 | P33: 3.9081253 | Q33: 26.074429 | R33: 23.710033 | S33: 2.4 | T33: 0.57012543 | U33: -41.897233 | V33: 9777 | W33: 11229.5 | X33: 12657.5 | Y33: 0 | Z33: 0 | AA33: 0 | AB33: 7318.1013 | AC33: 25.3 | AD33: 51.9 | AE33: 91.1 | AF33: 51.8 | AG33: C
A34: A388610 | B34: 지에프씨생명과학 | E34: 0 | F34: 0 | G34: -19.5 | H34: 3.1 | I34: 2.1 | J34: -24.4 | K34: 6560 | L34: 7149 | M34: 0.4689744 | N34: 23680.7 | O34: 0.30189141 | P34: 3.3384414 | Q34: 25.415872 | R34: 13.396338 | S34: 12 | T34: 1.3910355 | U34: -34.004024 | V34: 7238 | W34: 8023.5 | X34: 9287.1667 | Y34: 0 | Z34: 0 | AA34: 0 | AB34: 4034.2591 | AC34: 33.9 | AD34: 53 | AE34: 23.7 | AF34: 41.4 | AG34: D
A35: A340450 | B35: 지씨지놈 | E35: -11.1 | F35: -17.7 | G35: -61.6 | H35: 25.7 | I35: -38.7 | J35: -245.5 | K35: 5560 | L35: 89839 | M35: 4.9950484 | N35: 222973.05 | O35: 0.40291416 | P35: 3.1255011 | Q35: 25.065031 | R35: 10.292407 | S35: 14.8 | T35: -0.35842294 | U35: -32.769045 | V35: 6353 | W35: 6776.5 | X35: 7433.8333 | Y35: 0 | Z35: 0 | AA35: 0 | AB35: 2502.9254 | AC35: 27.3 | AD35: 36.5 | AE35: 40.7 | AF35: 34.6 | AG35: D
A36: A474650 | B36: 링크솔루션 | E36: 3.6 | F36: 53.1 | G36: -10.4 | H36: 87.3 | I36: 166 | J36: 72.9 | K36: 42500 | L36: 57418 | M36: 24.40265 | N36: 102450.55 | O36: 0.56044599 | P36: 3.4969622 | Q36: 25.848979 | R36: 17.307185 | S36: 8.5 | T36: -2.7459954 | U36: -28.451178 | V36: 48180 | W36: 51837.5 | X36: 58299.167 | Y36: 0 | Z36: 0 | AA36: 0 | AB36: 19468.936 | AC36: 23.6 | AD36: 80.4 | AE36: 60 | AF36: 59.3 | AG36: C
A37: A475430 | B37: 키스트론 | E37: 0 | F37: -0.6 | G37: -20.5 | H37: 17.1 | I37: -20.2 | J37: 13.5 | K37: 4680 | L37: 255623 | M37: 11.963156 | N37: 1201089.9 | O37: 0.21282587 | P37: 7.5231637 | Q37: 42.873606 | R37: 20.434107 | S37: 22.4 | T37: -0.74231177 | U37: -32.951289 | V37: 5107 | W37: 5293 | X37: 4816.5 | Y37: 0 | Z37: 0 | AA37: 0 | AB37: 2216.0885 | AC37: 37.9 | AD37: 53 | AE37: 10.4 | AF37: 39.9 | AG37: D
... A55: A226590 | B55: 엠디바이스 | E55: -0.8 | F55: 16.1 | G55: -563.4 | H55: 51.1 | I55: 325.1 | J55: -29.7 | K55: 16220 | L55: 103388 | M55: 16.769534 | N55: 313871.8 | O55: 0.32939563 | P55: 6.3029158 | Q55: 29.847546 | R55: 15.062512 | S55: 14.8 | T55: 3.2463399 | U55: -44.547009 | V55: 19010 | W55: 21805 | X55: 25970.833 | Y55: 0 | Z55: 0 | AA55: 0 | AB55: 15135.383 | AC55: 34 | AD55: 63.1 | AE55: 28.9 | AF55: 47.5 | AG55: D
A56: A393970 | B56: 대진첨단소재 | E56: 0 | F56: 0 | G56: 0 | H56: 0 | I56: 0 | J56: 0 | K56: 2825 | L56: 0 | N56: 0 | P56: 0 | T56: 0 | U56: 0 | V56: 2825 | W56: 2825 | X56: 2825 | Y56: 0 | Z56: 0 | AA56: 0 | AB56: 0 | AC56: 52.7 | AD56: 54.4 | AE56: 50 | AF56: 53 | AG56: C
A57: A489500 | B57: 엘케이켐 | E57: 1.1 | F57: 19.8 | G57: 39.8 | H57: 8.8 | I57: -0.3 | J57: 288.6 | K57: 28800 | L57: 41836 | M57: 12.048768 | N57: 122324.5 | O57: 0.34200835 | P57: 4.9891087 | Q57: 37.845244 | R57: 45.422014 | S57: -7.6 | T57: -0.8605852 | U57: -18.065434 | V57: 33715 | W57: 33217.5 | X57: 33662.5 | Y57: 0 | Z57: 0 | AA57: 0 | AB57: 12009.693 | AC57: 49.2 | AD57: 71 | AE57: 29.6 | AF57: 56.2 | AG57: C
A58: A479960 | B58: 위너스 | E58: 0 | F58: 0 | G58: 2.3 | H58: 2.6 | I58: 1.1 | J58: 16.4 | K58: 7780 | L58: 16167 | M58: 1.2577926 | N58: 70197.55 | O58: 0.23030718 | P58: 4.9183503 | Q58: 27.120315 | R58: 7.0342031 | S58: 20.1 | T58: 1.1703511 | U58: -43.826715 | V58: 9017 | W58: 10223.5 | X58: 10271.5 | Y58: 0 | Z58: 0 | AA58: 0 | AB58: 6152.5899 | AC58: 27.7 | AD58: 58.4 | AE58: 11.9 | AF58: 39.9 | AG58: D
A59: A463480 | B59: 모티브링크 | E59: 0.1 | F59: -0.1 | G59: 0.1 | H59: 3.7 | I59: -19.9 | J59: -53.8 | K59: 5600 | L59: 28513 | M59: 1.596728 | N59: 122790.25 | O59: 0.23220899 | P59: 3.7903181 | Q59: 27.53459 | R59: 7.618672 | S59: 19.9 | T59: 2.003643 | U59: -38.461538 | V59: 6297 | W59: 7091 | X59: 7350.8333 | Y59: 0 | Z59: 0 | AA59: 0 | AB59: 4002.0184 | AC59: 31.9 | AD59: 52 | AE59: 12.6 | AF59: 38.1 | AG59: D
A60: A303810 | B60: 동국생명과학 | E60: 0 | F60: 0 | G60: -0.1 | H60: -3.6 | I60: -9.7 | J60: -113.5 | K60: 2890 | L60: 63265 | M60: 1.8283585 | N60: 145464.65 | O60: 0.43491666 | P60: 1.4794594 | Q60: 30.814898 | R60: 14.161621 | S60: 16.7 | T60: 0.87260035 | U60: -15.373353 | V60: 2954 | W60: 3065.25 | X60: 3288.25 | Y60: 0 | Z60: 0 | AA60: 0 | AB60: 600.12192 | AC60: 51.6 | AD60: 46.9 | AE60: 47.4 | AF60: 48.4 | AG60: D
A61: A475830 | B61: 오름테라퓨틱 | E61: 36.5 | F61: -76.3 | G61: -949.2 | H61: 222.4 | I61: 1149.7 | J61: 3960.9 | K61: 64100 | L61: 115638 | M61: 74.123958 | N61: 206970.5 | O61: 0.55871731 | P61: 4.6409356 | Q61: 33.400989 | R61: 18.730637 | S61: 14.7 | T61: 0.62794349 | U61: -31.735889 | V61: 68050 | W61: 73210 | X61: 89981.667 | Y61: 0 | Z61: 0 | AA61: 0 | AB61: 32296.234 | AC61: 40.1 | AD61: 72.4 | AE61: 59.3 | AF61: 60.1 | AG61: C
A62: A240550 | B62: 동방메디컬 | E62: -8.1 | F62: 15.1 | G62: 297.5 | H62: 4.2 | I62: -50 | J62: -285.2 | K62: 6610 | L62: 105588 | M62: 6.9793668 | N62: 305676.75 | O62: 0.34542372 | P62: 3.8826618 | Q62: 38.738334 | R62: 24.909934 | S62: 13.8 | T62: 2.3219814 | U62: -4.2028986 | V62: 7254 | W62: 7324 | X62: 6975 | Y62: 0 | Z62: 0 | AA62: 0 | AB62: 2245.197 | AC62: 66 | AD62: 46.2 | AE62: 31.1 | AF62: 49.1 | AG62: D
A63: A212710 | B63: 아이에스티이 | E63: 2.4 | F63: -56.1 | G63: -129.1 | H63: 30.1 | I63: 100.8 | J63: 724.7 | K63: 11510 | L63: 181127 | M63: 20.847718 | N63: 446054.3 | O63: 0.40606491 | P63: 6.3058541 | Q63: 54.358427 | R63: 68.363385 | S63: -14 | T63: 5.985267 | U63: 19.64657 | V63: 11717 | W63: 11163 | X63: 9030.1667 | Y63: 0 | Z63: 1 | AA63: 1 | AB63: 4249.0688 | AC63: 76.8 | AD63: 64.3 | AE63: 42.2 | AF63: 63.6 | AG63: C
A64: A064400 | B64: LG씨엔에스 | E64: -1246.3 | F64: 2297.8 | G64: 11284 | H64: -7420.8 | I64: -15354.3 | J64: -17299.3 | K64: 126400 | L64: 3325944 | M64: 4203.9932 | N64: 3921297.5 | O64: 0.84817437 | P64: 9.0699357 | Q64: 68.984488 | R64: 78.150327 | S64: -9.2 | T64: -6.853353 | U64: 91.805766 | V64: 101930 | W64: 88540 | X64: 71996.667 | Y64: 1 | Z64: 1 | AA64: 1 | AB64: 92024.198 | AC64: 71.5 | AD64: 30.7 | AE64: 82.2 | AF64: 53.2 | AG64: C
A65: A452450 | B65: 피아이이 | E65: -0.4 | F65: 0 | G65: 0.2 | H65: 13.2 | I65: 16.7 | J65: -47.7 | K65: 5080 | L65: 149600 | M65: 7.59968 | N65: 999384.8 | O65: 0.14969209 | P65: 4.6137333 | Q65: 34.822202 | R65: 64.068963 | S65: -29.2 | T65: 1.1952191 | U65: -26.589595 | V65: 5508 | W65: 6069.5 | X65: 5895.5 | Y65: 0 | Z65: 0 | AA65: 0 | AB65: 3161.145 | AC65: 48.3 | AD65: 57.1 | AE65: 5.2 | AF65: 44.1 | AG65: D
A66: A462980 | B66: 아이지넷 | E66: -1 | F66: 0.4 | G66: 5.7 | H66: -32.1 | I66: -50.8 | J66: -116.8 | K66: 1421 | L66: 316336 | M66: 4.4951346 | N66: 271172.65 | O66: 1.1665483 | P66: 3.3220863 | Q66: 23.888911 | R66: 17.14578 | S66: 6.7 | T66: -10.176991 | U66: -37.123894 | V66: 1610.6 | W66: 1828.9 | X66: 2169.8 | Y66: 0 | Z66: 0 | AA66: 0 | AB66: 1040.6815 | AC66: 7.2 | AD66: 40.5 | AE66: 93.3 | AF66: 41.1 | AG66: D
A67: A482630 | B67: 삼양엔씨켐 | E67: 6.5 | F67: -76.3 | G67: -454 | H67: 12.8 | I67: -355.5 | J67: 369.6 | K67: 15710 | L67: 414417 | M67: 65.104911 | N67: 556210.95 | O67: 0.74507163 | P67: 6.0438847 | Q67: 37.286721 | R67: 28.709542 | S67: 8.6 | T67: 6.1486486 | U67: -20.334686 | V67: 18330 | W67: 19058 | X67: 18347 | Y67: 0 | Z67: 0 | AA67: 0 | AB67: 9514.9708 | AC67: 63.4 | AD67: 45.8 | AE67: 75.6 | AF67: 57 | AG67: C
...

Sheet 전체_전일자
A1: 코드 | B1: 코드명 | C1: 상장일 | D1: days_since_ipo | E1: 기관_일간 | F1: 기관_5일 | G1: 기관_20일 | H1: 외국인_일간 | I1: 외국인_5일 | J1: 외국인_20일 | K1: 현재가 | L1: 거래량 | M1: 거래대금(억) | N1: 20일평균거래량 | O1: RVOL(20) | P1: 변동성(30D) | Q1: RSI(14) | R1: 전일RSI(14) | S1: RSI변화량 | T1: 1일수익률(%) | U1: 20일수익률(%) | V1: 10일이평 | W1: 20일이평 | X1: 60일이평 | Y1: 10일선돌파 | Z1: 20일선돌파 | AA1: 60일선돌파 | AB1: BB폭 | AC1: 모멘텀스코어 | AD1: 수급스코어 | AE1: 거래량스코어 | AF1: 종합스코어 | AG1: 등급
A2: A458350 | B2: 에스팀 | E2: -0.1 | F2: -4.2 | G2: -13.4 | H2: 3.7 | I2: 12.2 | J2: 39 | K2: 5530 | L2: 40702 | M2: 2.2508206 | N2: 70708 | O2: 0.57563501 | P2: 2.4966132 | Q2: 7.307258 | R2: 5.9679061 | S2: 1.3 | T2: -2.8119508 | U2: -39.029768 | V2: 6390 | W2: 7249.5 | X2: 10586.333 | Y2: 0 | Z2: 0 | AA2: 0 | AB2: 4314.9576 | AC2: 17.5 | AD2: 53.7 | AE2: 30.4 | AF2: 38.2 | AG2: D
A3: A279570 | B3: 케이뱅크 | E3: 240.3 | F3: 1211.2 | G3: 2258.6 | H3: -63.4 | I3: -239.9 | J3: -1491.9 | K3: 5590 | L3: 1577166 | M3: 88.163579 | N3: 2297854.7 | O3: 0.68636455 | P3: 2.2139727 | Q3: 40.364261 | R3: 26.858767 | S3: 13.5 | T3: -0.17857143 | U3: -10.128617 | V3: 5557 | W3: 5661.5 | X3: 6200.1667 | Y3: 1 | Z3: 0 | AA3: 0 | AB3: 1038.1583 | AC3: 81 | AD3: 52.4 | AE3: 37.8 | AF3: 58.1 | AG3: C
A4: A490470 | B4: 세미파이브 | E4: -74.7 | F4: -81.3 | G4: -732.8 | H4: 236.9 | I4: -1472.1 | J4: -1500.4 | K4: 39500 | L4: 1032594 | M4: 407.87463 | N4: 1438503.2 | O4: 0.71782531 | P4: 6.883847 | Q4: 54.599983 | R4: 26.025712 | S4: 28.6 | T4: 2.1992238 | U4: -6.9493522 | V4: 38125 | W4: 39382.5 | X4: 33277.5 | Y4: 1 | Z4: 1 | AA4: 1 | AB4: 14616.973 | AC4: 90.7 | AD4: 27 | AE4: 43.7 | AF4: 49.4 | AG4: D
A5: A491000 | B5: 리브스메드 | E5: -172 | F5: -943 | G5: -1937.8 | H5: 99 | I5: -1058 | J5: 2455.5 | K5: 47950 | L5: 246292 | M5: 118.09701 | N5: 427429.9 | O5: 0.57621612 | P5: 6.298644 | Q5: 36.70545 | R5: 26.415546 | S5: 10.3 | T5: -4.6719682 | U5: -32.654494 | V5: 60295 | W5: 62707.5 | X5: 68557.5 | Y5: 0 | Z5: 0 | AA5: 0 | AB5: 28915.141 | AC5: 30.3 | AD5: 32.1 | AE5: 31.1 | AF5: 31.4 | AG5: D
A6: A476830 | B6: 알지노믹스 | E6: -666.5 | F6: -1189.2 | G6: -5686.3 | H6: 941.7 | I6: -690.4 | J6: 8416.4 | K6: 110900 | L6: 236799 | M6: 262.61009 | N6: 297174.4 | O6: 0.79683512 | P6: 4.7097514 | Q6: 31.768524 | R6: 19.069862 | S6: 12.7 | T6: -5.8573854 | U6: -36.952814 | V6: 131090 | W6: 145890 | X6: 178395 | Y6: 0 | Z6: 0 | AA6: 0 | AB6: 75769.834 | AC6: 17.8 | AD6: 34.3 | AE6: 55.6 | AF6: 33.6 | AG6: D
A7: A478340 | B7: 나라스페이스테크놀로지 | E7: -0.2 | F7: -1 | G7: -174.6 | H7: 42 | I7: -52.6 | J7: 32 | K7: 22150 | L7: 221529 | M7: 49.068674 | N7: 314990.8 | O7: 0.70328721 | P7: 5.4951302 | Q7: 34.001592 | R7: 28.212036 | S7: 5.8 | T7: -7.1278826 | U7: -35.043988 | V7: 27315 | W7: 29380 | X7: 35965.833 | Y7: 0 | Z7: 0 | AA7: 0 | AB7: 12939.275 | AC7: 17.9 | AD7: 49.9 | AE7: 42.2 | AF7: 38.8 | AG7: D
A8: A217590 | B8: 티엠씨 | E8: 5.8 | F8: -104.5 | G8: -1.1 | H8: 102 | I8: 205.9 | J8: 215.2 | K8: 18950 | L8: 297336 | M8: 56.345172 | N8: 591726.05 | O8: 0.50248929 | P8: 7.5467236 | Q8: 34.030874 | R8: 42.365873 | S8: -8.3 | T8: -9.5465394 | U8: -34.542314 | V8: 24970 | W8: 26972.5 | X8: 24539.667 | Y8: 0 | Z8: 0 | AA8: 0 | AB8: 15487.649 | AC8: 16.9 | AD8: 71.2 | AE8: 23.7 | AF8: 45.4 | AG8: D
A9: A464490 | B9: 쿼드메디슨 | E9: -1.6 | F9: 9.7 | G9: -8.2 | H9: 14.1 | I9: 30.9 | J9: 133.6 | K9: 8410 | L9: 88611 | M9: 7.4521851 | N9: 115005.3 | O9: 0.77049493 | P9: 3.0419549 | Q9: 24.542191 | R9: 6.9744788 | S9: 17.6 | T9: -0.70838253 | U9: -37.144993 | V9: 9594 | W9: 10616 | X9: 12978.667 | Y9: 0 | Z9: 0 | AA9: 0 | AB9: 5024.4606 | AC9: 26.8 | AD9: 65 | AE9: 51.9 | AF9: 50.9 | AG9: C
A10: A261520 | B10: 이지스 | E10: 0.1 | F10: 0 | G10: -53.1 | H10: 4.6 | I10: 8.9 | J10: 29.9 | K10: 4925 | L10: 69576 | M10: 3.426618 | N10: 74482.05 | O10: 0.93413111 | P10: 2.9703606 | Q10: 25.204251 | R10: 10.945857 | S10: 14.3 | T10: -3.4313725 | U10: -37.420584 | V10: 5604.5 | W10: 6262.25 | X10: 7817.0833 | Y10: 0 | Z10: 0 | AA10: 0 | AB10: 3257.1636 | AC10: 19.5 | AD10: 61.1 | AE10: 63.7 | AF10: 49.1 | AG10: D
A11: A950250 | B11: 테라뷰 | E11: 0.1 | F11: 0.1 | G11: -30.6 | H11: 40.5 | I11: -171 | J11: -152.8 | K11: 3410 | L11: 742199 | M11: 25.308986 | N11: 959310.6 | O11: 0.77367956 | P11: 3.8434233 | Q11: 22.206443 | R11: 10.707824 | S11: 11.5 | T11: -7.0844687 | U11: -49.630724 | V11: 4170.5 | W11: 4928 | X11: 6460.6667 | Y11: 0 | Z11: 0 | AA11: 0 | AB11: 3793.8144 | AC11: 4.2 | AD11: 52.6 | AE11: 52.6 | AF11: 38.1 | AG11: D
A12: A488900 | B12: 비츠로넥스텍 | E12: 0.5 | F12: -135.2 | G12: -459.9 | H12: 49.3 | I12: 34 | J12: 135 | K12: 12050 | L12: 113575 | M12: 13.685787 | N12: 138057.95 | O12: 0.82266179 | P12: 4.1536075 | Q12: 28.851943 | R12: 17.306434 | S12: 11.5 | T12: -3.6 | U12: -35.457954 | V12: 14506 | W12: 16299 | X12: 17843.333 | Y12: 0 | Z12: 0 | AA12: 0 | AB12: 8973.2318 | AC12: 23.8 | AD12: 60.2 | AE12: 57.8 | AF12: 48.8 | AG12: D
A13: A388210 | B13: 씨엠티엑스 | E13: 110.5 | F13: -1078.2 | G13: -4578.9 | H13: 446.5 | I13: 919.2 | J13: 1315.4 | K13: 108200 | L13: 148839 | M13: 161.0438 | N13: 126614.9 | O13: 1.1755252 | P13: 4.3556826 | Q13: 40.971718 | R13: 33.370612 | S13: 7.6 | T13: -4.9209139 | U13: -23.098792 | V13: 114240 | W13: 122125 | X13: 133943.33 | Y13: 0 | Z13: 0 | AA13: 0 | AB13: 41234.401 | AC13: 41.1 | AD13: 68 | AE13: 77.8 | AF13: 61.9 | AG13: C
... A24: A456160 | B24: 지투지바이오 | E24: -542.4 | F24: -701.9 | G24: 698.8 | H24: 519 | I24: -602.9 | J24: 451.5 | K24: 53700 | L24: 139447 | M24: 74.883039 | N24: 292731.4 | O24: 0.47636502 | P24: 4.8268948 | Q24: 32.887441 | R24: 12.69508 | S24: 20.2 | T24: -4.787234 | U24: -37.266355 | V24: 59810 | W24: 66590 | X24: 76433.333 | Y24: 0 | Z24: 0 | AA24: 0 | AB24: 34736.154 | AC24: 21.4 | AD24: 45.6 | AE24: 20 | AF24: 33.2 | AG24: D
A25: A309710 | B25: 아이티켐 | E25: 0 | F25: 0 | G25: 0 | H25: 0 | I25: 0 | J25: 0 | K25: 21000 | L25: 0 | N25: 0 | P25: 0 | Q25: 49.496106 | T25: 0 | U25: 0 | V25: 21000 | W25: 21000 | X25: 24496.667 | Y25: 0 | Z25: 0 | AA25: 0 | AB25: 0 | AC25: 67.2 | AD25: 58 | AE25: 50 | AF25: 59.2 | AG25: C
A26: A439260 | B26: 대한조선 | E26: -125.9 | F26: -315.7 | G26: -1453.3 | H26: 35 | I26: -310.4 | J26: -1086.3 | K26: 61400 | L26: 90363 | M26: 55.482882 | N26: 127306.05 | O26: 0.70980916 | P26: 2.5862324 | Q26: 27.140698 | R26: 10.216969 | S26: 16.9 | T26: -0.96774194 | U26: -31.396648 | V26: 65930 | W26: 72220 | X26: 85426.667 | Y26: 0 | Z26: 0 | AA26: 0 | AB26: 34016.368 | AC26: 32.8 | AD26: 20.8 | AE26: 43 | AF26: 28.8 | AG26: F
A27: A468530 | B27: 프로티나 | E27: -71.9 | F27: -327.2 | G27: -765.6 | H27: 148.3 | I27: 360.6 | J27: 1081.2 | K27: 36050 | L27: 113764 | M27: 41.011922 | N27: 82564.35 | O27: 1.3778828 | P27: 4.0771258 | Q27: 27.396393 | R27: 16.857031 | S27: 10.5 | T27: -5.0065876 | U27: -36.08156 | V27: 42195 | W27: 46605 | X27: 61378.333 | Y27: 0 | Z27: 0 | AA27: 0 | AB27: 22028.489 | AC27: 16.7 | AD27: 51.4 | AE27: 84.4 | AF27: 47.6 | AG27: D
A28: A475230 | B28: 엔알비 | E28: 4.1 | F28: 43.5 | G28: 10.3 | H28: 76.1 | I28: -40.7 | J28: 402.1 | K28: 12310 | L28: 120793 | M28: 14.869618 | N28: 140768.85 | O28: 0.85809467 | P28: 4.1940153 | Q28: 27.626879 | R28: 19.744582 | S28: 7.9 | T28: -6.7424242 | U28: -34.69496 | V28: 14145 | W28: 15718.5 | X28: 19740 | Y28: 0 | Z28: 0 | AA28: 0 | AB28: 7798.5615 | AC28: 15.2 | AD28: 77.2 | AE28: 59.3 | AF28: 55 | AG28: C
A29: A380550 | B29: 뉴로핏 | E29: -5.7 | F29: -3.6 | G29: -72.9 | H29: 78 | I29: 127 | J29: 124.6 | K29: 13240 | L29: 155353 | M29: 20.568737 | N29: 480317.65 | O29: 0.32343804 | P29: 4.1386828 | Q29: 31.523197 | R29: 21.625268 | S29: 9.9 | T29: -5.4285714 | U29: -34.129353 | V29: 15741 | W29: 17078 | X29: 20002.333 | Y29: 0 | Z29: 0 | AA29: 0 | AB29: 7349.5303 | AC29: 21.3 | AD29: 60.5 | AE29: 9.6 | AF29: 38.6 | AG29: D
A30: A484120 | B30: 도우인시스 | E30: -0.1 | F30: -2.6 | G30: -8.1 | H30: -4 | I30: -29.5 | J30: -107.4 | K30: 17320 | L30: 18400 | M30: 3.18688 | N30: 28874 | O30: 0.63725151 | P30: 3.7708342 | Q30: 36.769982 | R30: 17.701615 | S30: 19.1 | T30: 3.8992202 | U30: -25.344828 | V30: 18877 | W30: 20671 | X30: 20659.333 | Y30: 0 | Z30: 0 | AA30: 0 | AB30: 8607.4719 | AC30: 53.9 | AD30: 38.9 | AE30: 34.8 | AF30: 42.6 | AG30: D
A31: A331740 | B31: 아우토크립트 | E31: 82 | F31: 126.6 | G31: -197.1 | H31: -20.9 | I31: -76.4 | J31: -117.3 | K31: 12150 | L31: 110014 | M31: 13.366701 | N31: 103729.4 | O31: 1.0605865 | P31: 4.8669577 | Q31: 44.165905 | R31: 43.25613 | S31: 0.9 | T31: -11.892676 | U31: -20.275591 | V31: 12371 | W31: 12910.5 | X31: 15289.667 | Y31: 0 | Z31: 0 | AA31: 0 | AB31: 4214.4308 | AC31: 35.6 | AD31: 48.7 | AE31: 72.6 | AF31: 49.6 | AG31: D
A32: A234030 | B32: 싸이닉솔루션 | E32: 0 | F32: 6.9 | G32: 7.6 | H32: 9.8 | I32: 37.5 | J32: 35.4 | K32: 4715 | L32: 169215 | M32: 7.9784872 | N32: 214958.8 | O32: 0.78719736 | P32: 3.2687243 | Q32: 28.503675 | R32: 27.285414 | S32: 1.2 | T32: -3.6772217 | U32: -35.144429 | V32: 5314 | W32: 5977 | X32: 6709.3333 | Y32: 0 | Z32: 0 | AA32: 0 | AB32: 3290.7104 | AC32: 22.5 | AD32: 70 | AE32: 54.8 | AF32: 52.7 | AG32: C
A33: A463020 | B33: 뉴엔AI | E33: -7.8 | F33: -9.9 | G33: -27.2 | H33: -11.1 | I33: -17 | J33: -22.3 | K33: 8770 | L33: 72855 | M33: 6.3893835 | N33: 111649.95 | O33: 0.65253052 | P33: 3.8893995 | Q33: 28.518409 | R33: 24.510235 | S33: 4 | T33: -2.0111732 | U33: -40.421196 | V33: 10009 | W33: 11547.5 | X33: 12719.833 | Y33: 0 | Z33: 0 | AA33: 0 | AB33: 7752.7245 | AC33: 22.9 | AD33: 35.5 | AE33: 35.6 | AF33: 31.7 | AG33: D
A34: A388610 | B34: 지에프씨생명과학 | E34: 0 | F34: 0 | G34: -19.3 | H34: 1.5 | I34: -3.4 | J34: -33.4 | K34: 6470 | L34: 12403 | M34: 0.8024741 | N34: 24265.05 | O34: 0.51114669 | P34: 4.2595615 | Q34: 24.175609 | R34: 14.038816 | S34: 10.1 | T34: -2.7067669 | U34: -34.247967 | V34: 7353 | W34: 8192.5 | X34: 9347.6667 | Y34: 0 | Z34: 0 | AA34: 0 | AB34: 4133.2312 | AC34: 24.2 | AD34: 52.8 | AE34: 24.4 | AF34: 38.5 | AG34: D
A35: A340450 | B35: 지씨지놈 | E35: -15.8 | F35: -6.4 | G35: -48 | H35: 27.6 | I35: -82.3 | J35: -320.6 | K35: 5580 | L35: 184229 | M35: 10.279978 | N35: 237054.3 | O35: 0.77715949 | P35: 3.2064354 | Q35: 28.687696 | R35: 10.622978 | S35: 18.1 | T35: -2.2767075 | U35: -34.120425 | V35: 6491 | W35: 6912 | X35: 7464.6667 | Y35: 0 | Z35: 0 | AA35: 0 | AB35: 2566.623 | AC35: 29.2 | AD35: 37 | AE35: 53.3 | AF35: 37.9 | AG35: D
A36: A474650 | B36: 링크솔루션 | E36: 58.9 | F36: 49.5 | G36: -19.8 | H36: 18.3 | I36: 96.6 | J36: -143.9 | K36: 43700 | L36: 75558 | M36: 33.018846 | N36: 102714.1 | O36: 0.73561468 | P36: 3.5362804 | Q36: 32.002587 | R36: 20.290544 | S36: 11.7 | T36: -7.0212766 | U36: -26.430976 | V36: 48865 | W36: 52682.5 | X36: 58832.5 | Y36: 0 | Z36: 0 | AA36: 0 | AB36: 18486.556 | AC36: 24.2 | AD36: 71.6 | AE36: 46.7 | AF36: 52.4 | AG36: C
A37: A475430 | B37: 키스트론 | E37: 0 | F37: -0.6 | G37: -21.2 | H37: 8.1 | I37: 2.4 | J37: 70.1 | K37: 4715 | L37: 351864 | M37: 16.590388 | N37: 1777450.3 | O37: 0.19795997 | P37: 7.5277466 | Q37: 44.198035 | R37: 21.327995 | S37: 22.9 | T37: -4.1666667 | U37: -19.539249 | V37: 5108 | W37: 5408 | X37: 4810.5 | Y37: 0 | Z37: 0 | AA37: 0 | AB37: 2601.6303 | AC37: 47.7 | AD37: 57.9 | AE37: 2.2 | AF37: 43.7 | AG37: D
... A55: A226590 | B55: 엠디바이스 | E55: -2.8 | F55: 16.9 | G55: -616.1 | H55: 57.3 | I55: 218.3 | J55: 264.1 | K55: 15710 | L55: 180666 | M55: 28.382629 | N55: 336789.9 | O55: 0.53643533 | P55: 6.2367151 | Q55: 31.315302 | R55: 15.51615 | S55: 15.8 | T55: -3.2635468 | U55: -44.97373 | V55: 19478 | W55: 22456.5 | X55: 26156.333 | Y55: 0 | Z55: 0 | AA55: 0 | AB55: 15567.282 | AC55: 21.2 | AD55: 66 | AE55: 25.2 | AF55: 44.4 | AG55: D
A56: A393970 | B56: 대진첨단소재 | E56: 0 | F56: 0 | G56: 0 | H56: 0 | I56: 0 | J56: 0 | K56: 2825 | L56: 0 | N56: 0 | P56: 0 | Q56: 100 | T56: 0 | U56: 0 | V56: 2825 | W56: 2825 | X56: 2825 | Y56: 0 | Z56: 0 | AA56: 0 | AB56: 0 | AC56: 69.6 | AD56: 58 | AE56: 50 | AF56: 59.9 | AG56: C
A57: A489500 | B57: 엘케이켐 | E57: 15.4 | F57: 17.9 | G57: 38.8 | H57: -26.7 | I57: -127.5 | J57: 250.3 | K57: 29050 | L57: 85395 | M57: 24.807247 | N57: 125373.6 | O57: 0.68112426 | P57: 4.9887617 | Q57: 40.545006 | R57: 48.83168 | S57: -8.3 | T57: -5.0653595 | U57: -15.918958 | V57: 33845 | W57: 33535 | X57: 33782.5 | Y57: 0 | Z57: 0 | AA57: 0 | AB57: 11368.673 | AC57: 45.8 | AD57: 58.9 | AE57: 36.3 | AF57: 50.4 | AG57: C
A58: A479960 | B58: 위너스 | E58: 0 | F58: 0 | G58: 2.4 | H58: -7.2 | I58: -4.8 | J58: 14.1 | K58: 7690 | L58: 33481 | M58: 2.5746889 | N58: 161919.4 | O58: 0.20677572 | P58: 4.9056718 | Q58: 28.69905 | R58: 7.5618794 | S58: 21.1 | T58: -5.875153 | U58: -34.88569 | V58: 9246 | W58: 10527 | X58: 10296.833 | Y58: 0 | Z58: 0 | AA58: 0 | AB58: 6507.6874 | AC58: 18.1 | AD58: 54.1 | AE58: 3 | AF58: 33.1 | AG58: D
A59: A463480 | B59: 모티브링크 | E59: 0 | F59: 0 | G59: 0 | H59: -5.4 | I59: -30.4 | J59: -109 | K59: 5490 | L59: 55679 | M59: 3.0567771 | N59: 163394.5 | O59: 0.34076422 | P59: 3.7518913 | Q59: 28.781323 | R59: 8.0149071 | S59: 20.8 | T59: -3.3450704 | U59: -37.041284 | V59: 6428 | W59: 7266 | X59: 7378.5 | Y59: 0 | Z59: 0 | AA59: 0 | AB59: 4126.3905 | AC59: 23.4 | AD59: 46.1 | AE59: 12.6 | AF59: 32.6 | AG59: D
A60: A303810 | B60: 동국생명과학 | E60: 0 | F60: 0 | G60: -0.2 | H60: 0.7 | I60: -24.1 | J60: -111.9 | K60: 2865 | L60: 150018 | M60: 4.2980157 | N60: 149016.05 | O60: 1.0067238 | P60: 1.4591161 | Q60: 34.597327 | R60: 9.699514 | S60: 24.9 | T60: 1.4159292 | U60: -17.196532 | V60: 2967.5 | W60: 3091.5 | X60: 3299.25 | Y60: 0 | Z60: 0 | AA60: 0 | AB60: 652.44802 | AC60: 56.2 | AD60: 49.2 | AE60: 68.9 | AF60: 55.2 | AG60: C
A61: A475830 | B61: 오름테라퓨틱 | E61: -10.5 | F61: -40.5 | G61: -848.9 | H61: 496.9 | I61: 574.8 | J61: 3648.8 | K61: 63700 | L61: 170121 | M61: 108.36708 | N61: 211348.75 | O61: 0.80493024 | P61: 4.6389698 | Q61: 37.061807 | R61: 18.730637 | S61: 18.3 | T61: 0 | U61: -27.777778 | V61: 67930 | W61: 74700 | X61: 90868.333 | Y61: 0 | Z61: 0 | AA61: 0 | AB61: 36003.509 | AC61: 46.2 | AD61: 60.5 | AE61: 56.3 | AF61: 55.4 | AG61: C
A62: A240550 | B62: 동방메디컬 | E62: 14.1 | F62: 16.8 | G62: 304.9 | H62: 7.2 | I62: -122.2 | J62: -271.5 | K62: 6460 | L62: 147814 | M62: 9.5487844 | N62: 304899.15 | O62: 0.48479637 | P62: 3.8569005 | Q62: 38.344637 | R62: 26.46529 | S62: 11.9 | T62: -3.2934132 | U62: -7.5822604 | V62: 7383 | W62: 7338.5 | X62: 6982.1667 | Y62: 0 | Z62: 0 | AA62: 0 | AB62: 2181.6179 | AC62: 52.6 | AD62: 60.5 | AE62: 22.2 | AF62: 50.5 | AG62: C
A63: A212710 | B63: 아이에스티이 | E63: -0.4 | F63: -59.9 | G63: -131.4 | H63: 37.2 | I63: 93.6 | J63: 705.1 | K63: 10860 | L63: 248625 | M63: 27.000675 | N63: 452624.65 | O63: 0.5492962 | P63: 6.2437149 | Q63: 52.298068 | R63: 72.729561 | S63: -20.4 | T63: -6.5404475 | U63: 18.948521 | V63: 11680 | W63: 11068.5 | X63: 8977.8333 | Y63: 0 | Z63: 0 | AA63: 1 | AB63: 4450.5853 | AC63: 53.2 | AD63: 57.7 | AE63: 27.4 | AF63: 50.3 | AG63: C
A64: A064400 | B64: LG씨엔에스 | E64: 501.8 | F64: 4539.1 | G64: 12349.5 | H64: -11982.8 | I64: -8865 | J64: -10454.1 | K64: 135700 | L64: 7085039 | M64: 9614.3979 | N64: 3773866.4 | O64: 1.8773953 | P64: 8.9256957 | Q64: 76.450744 | R64: 84.953257 | S64: -8.5 | T64: -5.5671538 | U64: 108.76923 | V64: 96770 | W64: 85515 | X64: 70971.667 | Y64: 1 | Z64: 1 | AA64: 1 | AB64: 86826.945 | AC64: 76.8 | AD64: 50.4 | AE64: 94.8 | AF64: 67.2 | AG64: B
A65: A452450 | B65: 피아이이 | E65: 0.4 | F65: 0.5 | G65: 0.7 | H65: 1.2 | I65: 7.5 | J65: -47.2 | K65: 5020 | L65: 405012 | M65: 20.331602 | N65: 1014758.2 | O65: 0.39912166 | P65: 4.6266295 | Q65: 36.270053 | R65: 65.332418 | S65: -29.1 | T65: -1.953125 | U65: -27.351664 | V65: 5574 | W65: 6161.5 | X65: 5903.5 | Y65: 0 | Z65: 0 | AA65: 0 | AB65: 3104.0151 | AC65: 41.8 | AD65: 63.4 | AE65: 14.8 | AF65: 47.2 | AG65: D
A66: A462980 | B66: 아이지넷 | E66: 0.4 | F66: 1.5 | G66: 8.4 | H66: -14 | I66: -36.4 | J66: -81.7 | K66: 1582 | L66: 2187653 | M66: 34.60867 | N66: 260962.05 | O66: 8.3830312 | P66: 3.0067199 | Q66: 30.988831 | R66: 9.8307135 | S66: 21.2 | T66: 5.4666667 | U66: -31.663067 | V66: 1650.1 | W66: 1870.85 | X66: 2184.5333 | Y66: 0 | Z66: 0 | AA66: 0 | AB66: 1034.2971 | AC66: 43.7 | AD66: 52.1 | AE66: 100 | AF66: 59.2 | AG66: C
A67: A482630 | B67: 삼양엔씨켐 | E67: -39.1 | F67: -72.1 | G67: -473.9 | H67: 14.9 | I67: -445.6 | J67: 402 | K67: 14800 | L67: 270315 | M67: 40.00662 | N67: 544406.3 | O67: 0.49653173 | P67: 5.9074822 | Q67: 35.109463 | R67: 29.478548 | S67: 5.6 | T67: -1.986755 | U67: -23.395445 | V67: 18642 | W67: 19258.5 | X67: 18404.333 | Y67: 0 | Z67: 0 | AA67: 0 | AB67: 8988.1819 | AC67: 44.2 | AD67: 34.8 | AE67: 23 | AF67: 35.3 | AG67: D
...

Sheet RSI과매도
A1: 코드 | B1: 코드명 | C1: 상장일 | D1: days_since_ipo | E1: 기관_일간 | F1: 기관_5일 | G1: 기관_20일 | H1: 외국인_일간 | I1: 외국인_5일 | J1: 외국인_20일 | K1: 현재가 | L1: 거래량 | M1: 거래대금(억) | N1: 20일평균거래량 | O1: RVOL(20) | P1: 변동성(30D) | Q1: RSI(14) | R1: 전일RSI(14) | S1: RSI변화량 | T1: 1일수익률(%) | U1: 20일수익률(%) | V1: 10일이평 | W1: 20일이평 | X1: 60일이평 | Y1: 10일선돌파 | Z1: 20일선돌파 | AA1: 60일선돌파 | AB1: BB폭 | AC1: 모멘텀스코어 | AD1: 수급스코어 | AE1: 거래량스코어 | AF1: 종합스코어 | AG1: 등급
A2: A458350 | B2: 에스팀 | E2: 0.2 | F2: -3.7 | G2: -7.1 | H2: 10.5 | I2: 22 | J2: 28.1 | K2: 5590 | L2: 16455 | M2: 0.9198345 | N2: 66784.85 | O2: 0.24638822 | P2: 2.5403041 | Q2: 8.4920043 | R2: 5.5523594 | S2: 2.9 | T2: 1.084991 | U2: -38.163717 | V2: 6232 | W2: 7077 | X2: 10112.833 | Y2: 0 | Z2: 0 | AA2: 0 | AB2: 4211.545 | AC2: 24.5 | AD2: 60.8 | AE2: 16.3 | AF2: 41 | AG2: D
